Workbook

Sheet Manufacturer Info
A1: Manufacturer/Distributor | B1: Address 1 | C1: Address 2 | D1: City | E1: State | F1: Zip | G1: Phone | H1: Company Web Site | I1: Company E-Mail Address | J1: Toll Free | K1: Clinical Support | L1: Parent Company
A2: BRISTOL-MYERS SQUIBB CO. | B2: P. O. BOX 4500 | D2: PRINCETON | E2: NJ | F2: 08543 | G2: (609) 897-2000

Sheet REDBOOKSearchResults
A1: Formulation Number (DL) | B1: Manufacturer/Distributor | C1: Product Name | D1: Application | E1: Deactivated Status | F1: Deactivated Date | G1: Active Ingredient | H1: Generic | I1: Repackager | J1: Orange Book Code | K1: Code Type | L1: Identifier | M1: Form | N1: Strength | O1: Route | P1: Package Size | Q1: Unit Dose | R1: WAC Package Price | S1: WAC Effective Date | T1: New WAC | U1: New WAC Effective Date | V1: AWP Package Price | W1: AWP Unit Price | X1: AWP Effective Date | Y1: New AWP | Z1: New AWP Effective Date | AA1: DIRP Package Price | AB1: DIRP Effective Date | AC1: New DIRP | AD1: New DIRP Effective Date | AE1: SRP Package Price | AF1: SRP Effective Date | AG1: New SRP | AH1: New SRP Effective Date | AI1: Dea Class | AJ1: Significant Omission | AK1: Add'l Description
A2: 1 | B2: BRISTOL-MYERS SQUIBB CO. | C2: REVLIMID | D2: NDA | E2: N | G2: lenalidomide | H2: N | I2: N | K2: NDC | L2: 59572-0405-00 | M2: CAP | N2: 5 mg | O2: ORAL | P2: 100s ea | Q2: N | R2: 89155.06 | S2: 07/01/2024 | V2: 106986.08 | W2: 1069.86080 | X2: 07/01/2024 | AI2: RX
A3: =A2+1 -> 2 | B3: BRISTOL-MYERS SQUIBB CO. | C3: REVLIMID | D3: NDA | E3: N | G3: lenalidomide | H3: N | I3: N | K3: NDC | L3: 59572-0405-28 | M3: CAP | N3: 5 mg | O3: ORAL | P3: 28s ea | Q3: N | R3: 24963.40 | S3: 07/01/2024 | V3: 29956.08 | W3: 1069.86000 | X3: 07/01/2024 | AI3: RX
A4: =A3+1 -> 3 | B4: BRISTOL-MYERS SQUIBB CO. | C4: REVLIMID | E4: N | G4: lenalidomide | H4: N | I4: N | K4: NDC | L4: 59572-0420-21 | M4: CAP | N4: 20 mg | O4: ORAL | P4: 21s ea | Q4: N | R4: 18722.57 | S4: 07/01/2024 | V4: 22467.08 | W4: 1069.86095 | X4: 07/01/2024 | AI4: RX
A5: =A4+1 -> 4 | B5: BRISTOL-MYERS SQUIBB CO. | C5: REVLIMID | E5: N | G5: lenalidomide | H5: N | I5: N | K5: NDC | L5: 59572-0420-00 | M5: CAP | N5: 20 mg | O5: ORAL | P5: 100s ea | Q5: N | R5: 89155.06 | S5: 07/01/2024 | V5: 106986.08 | W5: 1069.86080 | X5: 07/01/2024 | AI5: RX
A6: =A5+1 -> 5 | B6: BRISTOL-MYERS SQUIBB CO. | C6: REVLIMID | D6: NDA | E6: N | G6: lenalidomide | H6: N | I6: N | J6: EE | K6: NDC | L6: 59572-0402-00 | M6: CAP | N6: 2.5 mg | O6: ORAL | P6: 100s ea | Q6: N | R6: 89155.06 | S6: 07/01/2024 | V6: 106986.08 | W6: 1069.86080 | X6: 07/01/2024 | AI6: RX
A7: =A6+1 -> 6 | B7: BRISTOL-MYERS SQUIBB CO. | C7: REVLIMID | D7: NDA | E7: N | G7: lenalidomide | H7: N | I7: N | J7: EE | K7: NDC | L7: 59572-0402-28 | M7: CAP | N7: 2.5 mg | O7: ORAL | P7: 28s ea | Q7: N | R7: 24963.40 | S7: 07/01/2024 | V7: 29956.08 | W7: 1069.86000 | X7: 07/01/2024 | AI7: RX
A8: =A7+1 -> 7 | B8: BRISTOL-MYERS SQUIBB CO. | C8: REVLIMID | D8: NDA | E8: N | G8: lenalidomide | H8: N | I8: N | K8: NDC | L8: 59572-0425-00 | M8: CAP | N8: 25 mg | O8: ORAL | P8: 100s ea | Q8: N | R8: 89155.06 | S8: 07/01/2024 | V8: 106986.08 | W8: 1069.86080 | X8: 07/01/2024 | AI8: RX
A9: =A8+1 -> 8 | B9: BRISTOL-MYERS SQUIBB CO. | C9: REVLIMID | D9: NDA | E9: N | G9: lenalidomide | H9: N | I9: N | K9: NDC | L9: 59572-0425-21 | M9: CAP | N9: 25 mg | O9: ORAL | P9: 21s ea | Q9: N | R9: 18722.57 | S9: 07/01/2024 | V9: 22467.08 | W9: 1069.86095 | X9: 07/01/2024 | AI9: RX
A10: =A9+1 -> 9 | B10: BRISTOL-MYERS SQUIBB CO. | C10: REVLIMID | D10: NDA | E10: N | G10: lenalidomide | H10: N | I10: N | K10: NDC | L10: 59572-0415-21 | M10: CAP | N10: 15 mg | O10: ORAL | P10: 21s ea | Q10: N | R10: 18722.57 | S10: 07/01/2024 | V10: 22467.08 | W10: 1069.86095 | X10: 07/01/2024 | AI10: RX
A11: =A10+1 -> 10 | B11: BRISTOL-MYERS SQUIBB CO. | C11: REVLIMID | D11: NDA | E11: N | G11: lenalidomide | H11: N | I11: N | K11: NDC | L11: 59572-0415-00 | M11: CAP | N11: 15 mg | O11: ORAL | P11: 100s ea | Q11: N | R11: 89155.06 | S11: 07/01/2024 | V11: 106986.08 | W11: 1069.86080 | X11: 07/01/2024 | AI11: RX
A12: =A11+1 -> 11 | B12: BRISTOL-MYERS SQUIBB CO. | C12: REVLIMID | D12: NDA | E12: N | G12: lenalidomide | H12: N | I12: N | K12: NDC | L12: 59572-0410-00 | M12: CAP | N12: 10 mg | O12: ORAL | P12: 100s ea | Q12: N | R12: 89155.06 | S12: 07/01/2024 | V12: 106986.08 | W12: 1069.86080 | X12: 07/01/2024 | AI12: RX
A13: =A12+1 -> 12 | B13: BRISTOL-MYERS SQUIBB CO. | C13: REVLIMID | D13: NDA | E13: N | G13: lenalidomide | H13: N | I13: N | K13: NDC | L13: 59572-0410-28 | M13: CAP | N13: 10 mg | O13: ORAL | P13: 28s ea | Q13: N | R13: 24963.40 | S13: 07/01/2024 | V13: 29956.08 | W13: 1069.86000 | X13: 07/01/2024 | AI13: RX
A15: Filtered Columns
A16: =A1 -> Formulation Number (DL) | B16: =C1 -> Product Name | C16: =L1 -> Identifier | D16: =N1 -> Strength | E16: =P1 -> Package Size | F16: =W1 -> AWP Unit Price
A17: =A2 -> 1 | B17: =C2 -> REVLIMID | C17: =L2 -> 59572-0405-00 | D17: =N2 -> 5 mg | E17: =P2 -> 100s ea | F17: =W2 -> 1069.86080
A18: =A3 -> 2 | B18: =C3 -> REVLIMID | C18: =L3 -> 59572-0405-28 | D18: =N3 -> 5 mg | E18: =P3 -> 28s ea | F18: =W3 -> 1069.86000
A19: =A4 -> 3 | B19: =C4 -> REVLIMID | C19: =L4 -> 59572-0420-21 | D19: =N4 -> 20 mg | E19: =P4 -> 21s ea | F19: =W4 -> 1069.86095
A20: =A5 -> 4 | B20: =C5 -> REVLIMID | C20: =L5 -> 59572-0420-00 | D20: =N5 -> 20 mg | E20: =P5 -> 100s ea | F20: =W5 -> 1069.86080
A21: =A6 -> 5 | B21: =C6 -> REVLIMID | C21: =L6 -> 59572-0402-00 | D21: =N6 -> 2.5 mg | E21: =P6 -> 100s ea | F21: =W6 -> 1069.86080
A22: =A7 -> 6 | B22: =C7 -> REVLIMID | C22: =L7 -> 59572-0402-28 | D22: =N7 -> 2.5 mg | E22: =P7 -> 28s ea | F22: =W7 -> 1069.86000
A23: =A8 -> 7 | B23: =C8 -> REVLIMID | C23: =L8 -> 59572-0425-00 | D23: =N8 -> 25 mg | E23: =P8 -> 100s ea | F23: =W8 -> 1069.86080
A24: =A9 -> 8 | B24: =C9 -> REVLIMID | C24: =L9 -> 59572-0425-21 | D24: =N9 -> 25 mg | E24: =P9 -> 21s ea | F24: =W9 -> 1069.86095
A25: =A10 -> 9 | B25: =C10 -> REVLIMID | C25: =L10 -> 59572-0415-21 | D25: =N10 -> 15 mg | E25: =P10 -> 21s ea | F25: =W10 -> 1069.86095
A26: =A11 -> 10 | B26: =C11 -> REVLIMID | C26: =L11 -> 59572-0415-00 | D26: =N11 -> 15 mg | E26: =P11 -> 100s ea | F26: =W11 -> 1069.86080
A27: =A12 -> 11 | B27: =C12 -> REVLIMID | C27: =L12 -> 59572-0410-00 | D27: =N12 -> 10 mg | E27: =P12 -> 100s ea | F27: =W12 -> 1069.86080
A28: =A13 -> 12 | B28: =C13 -> REVLIMID | C28: =L13 -> 59572-0410-28 | D28: =N13 -> 10 mg | E28: =P13 -> 28s ea | F28: =W13 -> 1069.86000
A31: 1 | B31: Product Name: REVLIMID | F31: 2 | G31: Product Name: REVLIMID | K31: 3 | L31: Product Name: REVLIMID | P31: 4 | Q31: Product Name: REVLIMID | U31: 5 | V31: Product Name: REVLIMID | Z31: 6 | AA31: Product Name: REVLIMID | AE31: 7 | AF31: Product Name: REVLIMID | AI31: 8 | AJ31: Product Name: REVLIMID | AN31: 9 | AO31: Product Name: REVLIMID | AS31: 10 | AT31: Product Name: REVLIMID | AX31: 11 | AY31: Product Name: REVLIMID | BC31: 12 | BD31: Product Name: REVLIMID
B32: Code: NDC | G32: Code: NDC | L32: Code: NDC | Q32: Code: NDC | V32: Code: NDC | AA32: Code: NDC | AF32: Code: NDC | AJ32: Code: NDC | AO32: Code: NDC | AT32: Code: NDC | AY32: Code: NDC | BD32: Code: NDC
B33: Identifier: 59572-0405-00 | G33: Identifier: 59572-0405-28 | L33: Identifier: 59572-0420-21 | Q33: Identifier: 59572-0420-00 | V33: Identifier: 59572-0402-00 | AA33: Identifier: 59572-0402-28 | AF33: Identifier: 59572-0425-00 | AJ33: Identifier: 59572-0425-21 | AO33: Identifier: 59572-0415-21 | AT33: Identifier: 59572-0415-00 | AY33: Identifier: 59572-0410-00 | BD33: Identifier: 59572-0410-28
B34: Effective Date | C34: Unit | D34: % Change | E34: Identifier | G34: Effective Date | H34: Unit | I34: % Change | J34: =$E34 -> Identifier | L34: Effective Date | M34: Unit | N34: % Change | O34: =$E34 -> Identifier | Q34: Effective Date | R34: Unit | S34: % Change | T34: =$E34 -> Identifier | V34: Effective Date | W34: Unit | X34: % Change | Y34: =$E34 -> Identifier | AA34: Effective Date | AB34: Unit | AC34: % Change | AD34: =$E34 -> Identifier | AF34: Effective Date | AG34: Unit | AH34: % Change | AI34: =$E34 -> Identifier | AJ34: Effective Date | AK34: Unit | AL34: % Change | AM34: =$E34 -> Identifier | AO34: Effective Date | AP34: Unit | AQ34: % Change | AR34: =$E34 -> Identifier | AT34: Effective Date | AU34: Unit | AV34: % Change | AW34: =$E34 -> Identifier | AY34: Effective Date | AZ34: Unit | BA34: % Change | BB34: =$E34 -> Identifier | BD34: Effective Date | BE34: Unit | BF34: % Change | BG34: =$E34 -> Identifier
B35: 45474 | C35: 1069.8608 | D35: 7 | E35: =REPLACE(B$33, 1, 12, "") -> 59572-0405-00 | G35: 45474 | H35: 1069.86 | I35: 7 | J35: =REPLACE(G$33, 1, 12, "") -> 59572-0405-28 | L35: 45474 | M35: 1069.861 | N35: 7 | O35: =REPLACE(L$33, 1, 12, "") -> 59572-0420-21 | Q35: 45474 | R35: 1069.8608 | S35: 7 | T35: =REPLACE(Q$33, 1, 12, "") -> 59572-0420-00 | V35: 45474 | W35: 1069.8608 | X35: 7 | Y35: =REPLACE(V$33, 1, 12, "") -> 59572-0402-00 | AA35: 45474 | AB35: 1069.86 | AC35: 7 | AD35: =REPLACE(AA$33, 1, 12, "") -> 59572-0402-28 | AF35: 45474 | AG35: 1069.8608 | AH35: 7 | AI35: =REPLACE(AF$33, 1, 12, "") -> 59572-0425-00 | AJ35: 45474 | AK35: 1069.861 | AL35: 7 | AM35: =REPLACE(AJ$33, 1, 12, "") -> 59572-0425-21 | AO35: 45474 | AP35: 1069.861 | AQ35: 7 | AR35: =REPLACE(AO$33, 1, 12, "") -> 59572-0415-21 | AT35: 45474 | AU35: 1069.8608 | AV35: 7 | AW35: =REPLACE(AT$33, 1, 12, "") -> 59572-0415-00 | AY35: 45474 | AZ35: 1069.8608 | BA35: 7 | BB35: =REPLACE(AY$33, 1, 12, "") -> 59572-0410-00 | BD35: 45474 | BE35: 1069.86 | BF35: 7 | BG35: =REPLACE(BD$33, 1, 12, "") -> 59572-0410-28
B36: 44562 | C36: 999.8699 | D36: 4.5 | E36: =REPLACE(B$33, 1, 12, "") -> 59572-0405-00 | G36: 44562 | H36: 999.86929 | I36: 4.5 | J36: =REPLACE(G$33, 1, 12, "") -> 59572-0405-28 | L36: 44562 | M36: 999.87048 | N36: 4.5 | O36: =REPLACE(L$33, 1, 12, "") -> 59572-0420-21 | Q36: 44562 | R36: 999.8699 | S36: 4.5 | T36: =REPLACE(Q$33, 1, 12, "") -> 59572-0420-00 | V36: 44562 | W36: 999.8699 | X36: 4.5 | Y36: =REPLACE(V$33, 1, 12, "") -> 59572-0402-00 | AA36: 44562 | AB36: 999.86929 | AC36: 4.5 | AD36: =REPLACE(AA$33, 1, 12, "") -> 59572-0402-28 | AF36: 44562 | AG36: 999.8699 | AH36: 4.5 | AI36: =REPLACE(AF$33, 1, 12, "") -> 59572-0425-00 | AJ36: 44562 | AK36: 999.87048 | AL36: 4.5 | AM36: =REPLACE(AJ$33, 1, 12, "") -> 59572-0425-21 | AO36: 44562 | AP36: 999.87048 | AQ36: 4.5 | AR36: =REPLACE(AO$33, 1, 12, "") -> 59572-0415-21 | AT36: 44562 | AU36: 999.8699 | AV36: 4.5 | AW36: =REPLACE(AT$33, 1, 12, "") -> 59572-0415-00 | AY36: 44562 | AZ36: 999.8699 | BA36: 4.5 | BB36: =REPLACE(AY$33, 1, 12, "") -> 59572-0410-00 | BD36: 44562 | BE36: 999.86929 | BF36: 4.5 | BG36: =REPLACE(BD$33, 1, 12, "") -> 59572-0410-28
B37: 44197 | C37: 956.8133 | D37: 4.5 | E37: =REPLACE(B$33, 1, 12, "") -> 59572-0405-00 | G37: 44197 | H37: 956.81286 | I37: 4.5 | J37: =REPLACE(G$33, 1, 12, "") -> 59572-0405-28 | L37: 44197 | M37: 956.81381 | N37: 4.5 | O37: =REPLACE(L$33, 1, 12, "") -> 59572-0420-21 | Q37: 44197 | R37: 956.8133 | S37: 4.5 | T37: =REPLACE(Q$33, 1, 12, "") -> 59572-0420-00 | V37: 44197 | W37: 956.8133 | X37: 4.5 | Y37: =REPLACE(V$33, 1, 12, "") -> 59572-0402-00 | AA37: 44197 | AB37: 956.81286 | AC37: 4.5 | AD37: =REPLACE(AA$33, 1, 12, "") -> 59572-0402-28 | AF37: 44197 | AG37: 956.8133 | AH37: 4.5 | AI37: =REPLACE(AF$33, 1, 12, "") -> 59572-0425-00 | AJ37: 44197 | AK37: 956.81381 | AL37: 4.5 | AM37: =REPLACE(AJ$33, 1, 12, "") -> 59572-0425-21 | AO37: 44197 | AP37: 956.81381 | AQ37: 4.5 | AR37: =REPLACE(AO$33, 1, 12, "") -> 59572-0415-21 | AT37: 44197 | AU37: 956.8133 | AV37: 4.5 | AW37: =REPLACE(AT$33, 1, 12, "") -> 59572-0415-00 | AY37: 44197 | AZ37: 956.8133 | BA37: 4.5 | BB37: =REPLACE(AY$33, 1, 12, "") -> 59572-0410-00 | BD37: 44197 | BE37: 956.81286 | BF37: 4.5 | BG37: =REPLACE(BD$33, 1, 12, "") -> 59572-0410-28
B38: 43831 | C38: 915.6108 | D38: 6 | E38: =REPLACE(B$33, 1, 12, "") -> 59572-0405-00 | G38: 43831 | H38: 915.61036 | I38: 6 | J38: =REPLACE(G$33, 1, 12, "") -> 59572-0405-28 | L38: 43831 | M38: 915.61143 | N38: 6 | O38: =REPLACE(L$33, 1, 12, "") -> 59572-0420-21 | Q38: 43831 | R38: 915.6108 | S38: 6 | T38: =REPLACE(Q$33, 1, 12, "") -> 59572-0420-00 | V38: 43831 | W38: 915.6108 | X38: 6 | Y38: =REPLACE(V$33, 1, 12, "") -> 59572-0402-00 | AA38: 43831 | AB38: 915.61036 | AC38: 6 | AD38: =REPLACE(AA$33, 1, 12, "") -> 59572-0402-28 | AF38: 43831 | AG38: 915.6108 | AH38: 6 | AI38: =REPLACE(AF$33, 1, 12, "") -> 59572-0425-00 | AJ38: 43831 | AK38: 915.61143 | AL38: 6 | AM38: =REPLACE(AJ$33, 1, 12, "") -> 59572-0425-21 | AO38: 43831 | AP38: 915.61143 | AQ38: 6 | AR38: =REPLACE(AO$33, 1, 12, "") -> 59572-0415-21 | AT38: 43831 | AU38: 915.6108 | AV38: 6 | AW38: =REPLACE(AT$33, 1, 12, "") -> 59572-0415-00 | AY38: 43831 | AZ38: 915.6108 | BA38: 6 | BB38: =REPLACE(AY$33, 1, 12, "") -> 59572-0410-00 | BD38: 43831 | BE38: 915.61036 | BF38: 6 | BG38: =REPLACE(BD$33, 1, 12, "") -> 59572-0410-28
B39: 43468 | C39: 863.7838 | D39: 3.5 | E39: =REPLACE(B$33, 1, 12, "") -> 59572-0405-00 | G39: 43468 | H39: 863.78321 | I39: 3.5 | J39: =REPLACE(G$33, 1, 12, "") -> 59572-0405-28 | L39: 43468 | M39: 863.78476 | N39: 3.5 | O39: =REPLACE(L$33, 1, 12, "") -> 59572-0420-21 | Q39: 43468 | R39: 863.7838 | S39: 3.5 | T39: =REPLACE(Q$33, 1, 12, "") -> 59572-0420-00 | V39: 43468 | W39: 863.7838 | X39: 3.5 | Y39: =REPLACE(V$33, 1, 12, "") -> 59572-0402-00 | AA39: 43468 | AB39: 863.78321 | AC39: 3.5 | AD39: =REPLACE(AA$33, 1, 12, "") -> 59572-0402-28 | AF39: 43468 | AG39: 863.7838 | AH39: 3.5 | AI39: =REPLACE(AF$33, 1, 12, "") -> 59572-0425-00 | AJ39: 43468 | AK39: 863.78476 | AL39: 3.5 | AM39: =REPLACE(AJ$33, 1, 12, "") -> 59572-0425-21 | AO39: 43468 | AP39: 863.78476 | AQ39: 3.5 | AR39: =REPLACE(AO$33, 1, 12, "") -> 59572-0415-21 | AT39: 43468 | AU39: 863.7838 | AV39: 3.5 | AW39: =REPLACE(AT$33, 1, 12, "") -> 59572-0415-00 | AY39: 43468 | AZ39: 863.7838 | BA39: 3.5 | BB39: =REPLACE(AY$33, 1, 12, "") -> 59572-0410-00 | BD39: 43468 | BE39: 863.78321 | BF39: 3.5 | BG39: =REPLACE(BD$33, 1, 12, "") -> 59572-0410-28
B40: 43291 | C40: 834.5738 | D40: 5 | E40: =REPLACE(B$33, 1, 12, "") -> 59572-0405-00 | G40: 43291 | H40: 834.57286 | I40: 5 | J40: =REPLACE(G$33, 1, 12, "") -> 59572-0405-28 | L40: 43291 | M40: 834.57429 | N40: 5 | O40: =REPLACE(L$33, 1, 12, "") -> 59572-0420-21 | Q40: 43291 | R40: 834.5738 | S40: 5 | T40: =REPLACE(Q$33, 1, 12, "") -> 59572-0420-00 | V40: 43291 | W40: 834.5738 | X40: 5 | Y40: =REPLACE(V$33, 1, 12, "") -> 59572-0402-00 | AA40: 43291 | AB40: 834.57286 | AC40: 5 | AD40: =REPLACE(AA$33, 1, 12, "") -> 59572-0402-28 | AF40: 43291 | AG40: 834.5738 | AH40: 5 | AI40: =REPLACE(AF$33, 1, 12, "") -> 59572-0425-00 | AJ40: 43291 | AK40: 834.57429 | AL40: 5 | AM40: =REPLACE(AJ$33, 1, 12, "") -> 59572-0425-21 | AO40: 43291 | AP40: 834.57429 | AQ40: 5 | AR40: =REPLACE(AO$33, 1, 12, "") -> 59572-0415-21 | AT40: 43291 | AU40: 834.5738 | AV40: 5 | AW40: =REPLACE(AT$33, 1, 12, "") -> 59572-0415-00 | AY40: 43291 | AZ40: 834.5738 | BA40: 5 | BB40: =REPLACE(AY$33, 1, 12, "") -> 59572-0410-00 | BD40: 43291 | BE40: 834.57286 | BF40: 5 | BG40: =REPLACE(BD$33, 1, 12, "") -> 59572-0410-28
B41: 43028 | C41: 794.8321 | D41: 9 | E41: =REPLACE(B$33, 1, 12, "") -> 59572-0405-00 | G41: 43028 | H41: 794.83179 | I41: 9 | J41: =REPLACE(G$33, 1, 12, "") -> 59572-0405-28 | L41: 43028 | M41: 794.83238 | N41: 9 | O41: =REPLACE(L$33, 1, 12, "") -> 59572-0420-21 | Q41: 43028 | R41: 794.8321 | S41: 9 | T41: =REPLACE(Q$33, 1, 12, "") -> 59572-0420-00 | V41: 43028 | W41: 794.8321 | X41: 9 | Y41: =REPLACE(V$33, 1, 12, "") -> 59572-0402-00 | AA41: 43028 | AB41: 794.83179 | AC41: 9 | AD41: =REPLACE(AA$33, 1, 12, "") -> 59572-0402-28 | AF41: 43028 | AG41: 794.8321 | AH41: 9 | AI41: =REPLACE(AF$33, 1, 12, "") -> 59572-0425-00 | AJ41: 43028 | AK41: 794.83238 | AL41: 9 | AM41: =REPLACE(AJ$33, 1, 12, "") -> 59572-0425-21 | AO41: 43028 | AP41: 794.83238 | AQ41: 9 | AR41: =REPLACE(AO$33, 1, 12, "") -> 59572-0415-21 | AT41: 43028 | AU41: 794.8321 | AV41: 9 | AW41: =REPLACE(AT$33, 1, 12, "") -> 59572-0415-00 | AY41: 43028 | AZ41: 794.8321 | BA41: 9 | BB41: =REPLACE(AY$33, 1, 12, "") -> 59572-0410-00 | BD41: 43028 | BE41: 794.83179 | BF41: 9 | BG41: =REPLACE(BD$33, 1, 12, "") -> 59572-0410-28
B42: 42927 | C42: 729.2038 | D42: 1.8 | E42: =REPLACE(B$33, 1, 12, "") -> 59572-0405-00 | G42: 42927 | H42: 729.20321 | I42: 1.8 | J42: =REPLACE(G$33, 1, 12, "") -> 59572-0405-28 | L42: 42927 | M42: 729.20381 | N42: 1.7 | O42: =REPLACE(L$33, 1, 12, "") -> 59572-0420-21 | Q42: 42927 | R42: 729.2038 | S42: 1.8 | T42: =REPLACE(Q$33, 1, 12, "") -> 59572-0420-00 | V42: 42927 | W42: 729.2038 | X42: 1.8 | Y42: =REPLACE(V$33, 1, 12, "") -> 59572-0402-00 | AA42: 42927 | AB42: 729.20321 | AC42: 1.8 | AD42: =REPLACE(AA$33, 1, 12, "") -> 59572-0402-28 | AF42: 42927 | AG42: 729.2038 | AH42: 1.8 | AI42: =REPLACE(AF$33, 1, 12, "") -> 59572-0425-00 | AJ42: 42927 | AK42: 729.20381 | AL42: 1.7 | AM42: =REPLACE(AJ$33, 1, 12, "") -> 59572-0425-21 | AO42: 42927 | AP42: 729.20381 | AQ42: 1.7 | AR42: =REPLACE(AO$33, 1, 12, "") -> 59572-0415-21 | AT42: 42927 | AU42: 729.2038 | AV42: 1.8 | AW42: =REPLACE(AT$33, 1, 12, "") -> 59572-0415-00 | AY42: 42927 | AZ42: 729.2038 | BA42: 1.8 | BB42: =REPLACE(AY$33, 1, 12, "") -> 59572-0410-00 | BD42: 42927 | BE42: 729.20321 | BF42: 1.8 | BG42: =REPLACE(BD$33, 1, 12, "") -> 59572-0410-28
B43: 42746 | C43: 716.6622 | D43: 8 | E43: =REPLACE(B$33, 1, 12, "") -> 59572-0405-00 | G43: 42746 | H43: 716.66143 | I43: 8 | J43: =REPLACE(G$33, 1, 12, "") -> 59572-0405-28 | L43: 42746 | M43: 716.66238 | N43: 8 | O43: =REPLACE(L$33, 1, 12, "") -> 59572-0420-21 | Q43: 42746 | R43: 716.6622 | S43: 8 | T43: =REPLACE(Q$33, 1, 12, "") -> 59572-0420-00 | V43: 42746 | W43: 716.6622 | X43: 8 | Y43: =REPLACE(V$33, 1, 12, "") -> 59572-0402-00 | AA43: 42746 | AB43: 716.66143 | AC43: 8 | AD43: =REPLACE(AA$33, 1, 12, "") -> 59572-0402-28 | AF43: 42746 | AG43: 716.6622 | AH43: 8 | AI43: =REPLACE(AF$33, 1, 12, "") -> 59572-0425-00 | AJ43: 42746 | AK43: 716.66238 | AL43: 8 | AM43: =REPLACE(AJ$33, 1, 12, "") -> 59572-0425-21 | AO43: 42746 | AP43: 716.66238 | AQ43: 8 | AR43: =REPLACE(AO$33, 1, 12, "") -> 59572-0415-21 | AT43: 42746 | AU43: 716.6622 | AV43: 8 | AW43: =REPLACE(AT$33, 1, 12, "") -> 59572-0415-00 | AY43: 42746 | AZ43: 716.6622 | BA43: 8 | BB43: =REPLACE(AY$33, 1, 12, "") -> 59572-0410-00 | BD43: 42746 | BE43: 716.66143 | BF43: 8 | BG43: =REPLACE(BD$33, 1, 12, "") -> 59572-0410-28
...

Sheet Revlimid_Price_Csv
A1: =REDBOOKSearchResults!B31 -> Product Name: REVLIMID
A2: =REDBOOKSearchResults!B34 -> Effective Date | B2: =REDBOOKSearchResults!C34 -> Unit | C2: =REDBOOKSearchResults!D34 -> % Change | D2: =REDBOOKSearchResults!E34 -> Identifier | E2: Dosage | F2: Package Size
A3: =REDBOOKSearchResults!B35 -> 45474 | B3: =REDBOOKSearchResults!C35 -> 1069.8608 | C3: =REDBOOKSearchResults!D35 -> 7 | D3: =REDBOOKSearchResults!E35 -> 59572-0405-00 | E3: =INDEX(REDBOOKSearchResults!$N$2:$N$13, MATCH(D3, REDBOOKSearchResults!$L$2:$L$13, 0)) -> 5 mg | F3: =INDEX(REDBOOKSearchResults!$A$1:$AK$100, MATCH($D3, REDBOOKSearchResults!$L$1:$L$100, 0), MATCH(F$2, REDBOOKSearchResults!$1:$1, 0)) -> 100s ea
A4: =REDBOOKSearchResults!B36 -> 44562 | B4: =REDBOOKSearchResults!C36 -> 999.8699 | C4: =REDBOOKSearchResults!D36 -> 4.5 | D4: =REDBOOKSearchResults!E36 -> 59572-0405-00 | E4: =INDEX(REDBOOKSearchResults!$N$2:$N$13, MATCH(D4, REDBOOKSearchResults!$L$2:$L$13, 0)) -> 5 mg | F4: =INDEX(REDBOOKSearchResults!$A$1:$AK$100, MATCH($D4, REDBOOKSearchResults!$L$1:$L$100, 0), MATCH(F$2, REDBOOKSearchResults!$1:$1, 0)) -> 100s ea
A5: =REDBOOKSearchResults!B37 -> 44197 | B5: =REDBOOKSearchResults!C37 -> 956.8133 | C5: =REDBOOKSearchResults!D37 -> 4.5 | D5: =REDBOOKSearchResults!E37 -> 59572-0405-00 | E5: =INDEX(REDBOOKSearchResults!$N$2:$N$13, MATCH(D5, REDBOOKSearchResults!$L$2:$L$13, 0)) -> 5 mg | F5: =INDEX(REDBOOKSearchResults!$A$1:$AK$100, MATCH($D5, REDBOOKSearchResults!$L$1:$L$100, 0), MATCH(F$2, REDBOOKSearchResults!$1:$1, 0)) -> 100s ea
A6: =REDBOOKSearchResults!B38 -> 43831 | B6: =REDBOOKSearchResults!C38 -> 915.6108 | C6: =REDBOOKSearchResults!D38 -> 6 | D6: =REDBOOKSearchResults!E38 -> 59572-0405-00 | E6: =INDEX(REDBOOKSearchResults!$N$2:$N$13, MATCH(D6, REDBOOKSearchResults!$L$2:$L$13, 0)) -> 5 mg | F6: =INDEX(REDBOOKSearchResults!$A$1:$AK$100, MATCH($D6, REDBOOKSearchResults!$L$1:$L$100, 0), MATCH(F$2, REDBOOKSearchResults!$1:$1, 0)) -> 100s ea
A7: =REDBOOKSearchResults!B39 -> 43468 | B7: =REDBOOKSearchResults!C39 -> 863.7838 | C7: =REDBOOKSearchResults!D39 -> 3.5 | D7: =REDBOOKSearchResults!E39 -> 59572-0405-00 | E7: =INDEX(REDBOOKSearchResults!$N$2:$N$13, MATCH(D7, REDBOOKSearchResults!$L$2:$L$13, 0)) -> 5 mg | F7: =INDEX(REDBOOKSearchResults!$A$1:$AK$100, MATCH($D7, REDBOOKSearchResults!$L$1:$L$100, 0), MATCH(F$2, REDBOOKSearchResults!$1:$1, 0)) -> 100s ea
A8: =REDBOOKSearchResults!B40 -> 43291 | B8: =REDBOOKSearchResults!C40 -> 834.5738 | C8: =REDBOOKSearchResults!D40 -> 5 | D8: =REDBOOKSearchResults!E40 -> 59572-0405-00 | E8: =INDEX(REDBOOKSearchResults!$N$2:$N$13, MATCH(D8, REDBOOKSearchResults!$L$2:$L$13, 0)) -> 5 mg | F8: =INDEX(REDBOOKSearchResults!$A$1:$AK$100, MATCH($D8, REDBOOKSearchResults!$L$1:$L$100, 0), MATCH(F$2, REDBOOKSearchResults!$1:$1, 0)) -> 100s ea
A9: =REDBOOKSearchResults!B41 -> 43028 | B9: =REDBOOKSearchResults!C41 -> 794.8321 | C9: =REDBOOKSearchResults!D41 -> 9 | D9: =REDBOOKSearchResults!E41 -> 59572-0405-00 | E9: =INDEX(REDBOOKSearchResults!$N$2:$N$13, MATCH(D9, REDBOOKSearchResults!$L$2:$L$13, 0)) -> 5 mg | F9: =INDEX(REDBOOKSearchResults!$A$1:$AK$100, MATCH($D9, REDBOOKSearchResults!$L$1:$L$100, 0), MATCH(F$2, REDBOOKSearchResults!$1:$1, 0)) -> 100s ea
A10: =REDBOOKSearchResults!B42 -> 42927 | B10: =REDBOOKSearchResults!C42 -> 729.2038 | C10: =REDBOOKSearchResults!D42 -> 1.8 | D10: =REDBOOKSearchResults!E42 -> 59572-0405-00 | E10: =INDEX(REDBOOKSearchResults!$N$2:$N$13, MATCH(D10, REDBOOKSearchResults!$L$2:$L$13, 0)) -> 5 mg | F10: =INDEX(REDBOOKSearchResults!$A$1:$AK$100, MATCH($D10, REDBOOKSearchResults!$L$1:$L$100, 0), MATCH(F$2, REDBOOKSearchResults!$1:$1, 0)) -> 100s ea
A11: =REDBOOKSearchResults!B43 -> 42746 | B11: =REDBOOKSearchResults!C43 -> 716.6622 | C11: =REDBOOKSearchResults!D43 -> 8 | D11: =REDBOOKSearchResults!E43 -> 59572-0405-00 | E11: =INDEX(REDBOOKSearchResults!$N$2:$N$13, MATCH(D11, REDBOOKSearchResults!$L$2:$L$13, 0)) -> 5 mg | F11: =INDEX(REDBOOKSearchResults!$A$1:$AK$100, MATCH($D11, REDBOOKSearchResults!$L$1:$L$100, 0), MATCH(F$2, REDBOOKSearchResults!$1:$1, 0)) -> 100s ea
A12: =REDBOOKSearchResults!B44 -> 42602 | B12: =REDBOOKSearchResults!C44 -> 663.5762 | C12: =REDBOOKSearchResults!D44 -> 3 | D12: =REDBOOKSearchResults!E44 -> 59572-0405-00 | E12: =INDEX(REDBOOKSearchResults!$N$2:$N$13, MATCH(D12, REDBOOKSearchResults!$L$2:$L$13, 0)) -> 5 mg | F12: =INDEX(REDBOOKSearchResults!$A$1:$AK$100, MATCH($D12, REDBOOKSearchResults!$L$1:$L$100, 0), MATCH(F$2, REDBOOKSearchResults!$1:$1, 0)) -> 100s ea
A13: =REDBOOKSearchResults!B45 -> 42439 | B13: =REDBOOKSearchResults!C45 -> 644.2487 | C13: =REDBOOKSearchResults!D45 -> 6.8 | D13: =REDBOOKSearchResults!E45 -> 59572-0405-00 | E13: =INDEX(REDBOOKSearchResults!$N$2:$N$13, MATCH(D13, REDBOOKSearchResults!$L$2:$L$13, 0)) -> 5 mg | F13: =INDEX(REDBOOKSearchResults!$A$1:$AK$100, MATCH($D13, REDBOOKSearchResults!$L$1:$L$100, 0), MATCH(F$2, REDBOOKSearchResults!$1:$1, 0)) -> 100s ea
A14: =REDBOOKSearchResults!B46 -> 42279 | B14: =REDBOOKSearchResults!C46 -> 603.2291 | C14: =REDBOOKSearchResults!D46 -> 4 | D14: =REDBOOKSearchResults!E46 -> 59572-0405-00 | E14: =INDEX(REDBOOKSearchResults!$N$2:$N$13, MATCH(D14, REDBOOKSearchResults!$L$2:$L$13, 0)) -> 5 mg | F14: =INDEX(REDBOOKSearchResults!$A$1:$AK$100, MATCH($D14, REDBOOKSearchResults!$L$1:$L$100, 0), MATCH(F$2, REDBOOKSearchResults!$1:$1, 0)) -> 100s ea
... A29: =REDBOOKSearchResults!B61 -> 38715 | B29: =REDBOOKSearchResults!C61 -> 258 | C29: =REDBOOKSearchResults!D61 -> 0 | D29: =REDBOOKSearchResults!E61 -> 59572-0405-00 | E29: =INDEX(REDBOOKSearchResults!$N$2:$N$13, MATCH(D29, REDBOOKSearchResults!$L$2:$L$13, 0)) -> 5 mg | F29: =INDEX(REDBOOKSearchResults!$A$1:$AK$100, MATCH($D29, REDBOOKSearchResults!$L$1:$L$100, 0), MATCH(F$2, REDBOOKSearchResults!$1:$1, 0)) -> 100s ea
A30: =REDBOOKSearchResults!G35 -> 45474 | B30: =REDBOOKSearchResults!H35 -> 1069.86 | C30: =REDBOOKSearchResults!I35 -> 7 | D30: =REDBOOKSearchResults!J35 -> 59572-0405-28 | E30: =INDEX(REDBOOKSearchResults!$N$2:$N$13, MATCH(D30, REDBOOKSearchResults!$L$2:$L$13, 0)) -> 5 mg | F30: =INDEX(REDBOOKSearchResults!$A$1:$AK$100, MATCH($D30, REDBOOKSearchResults!$L$1:$L$100, 0), MATCH(F$2, REDBOOKSearchResults!$1:$1, 0)) -> 28s ea
A31: =REDBOOKSearchResults!G36 -> 44562 | B31: =REDBOOKSearchResults!H36 -> 999.86929 | C31: =REDBOOKSearchResults!I36 -> 4.5 | D31: =REDBOOKSearchResults!J36 -> 59572-0405-28 | E31: =INDEX(REDBOOKSearchResults!$N$2:$N$13, MATCH(D31, REDBOOKSearchResults!$L$2:$L$13, 0)) -> 5 mg | F31: =INDEX(REDBOOKSearchResults!$A$1:$AK$100, MATCH($D31, REDBOOKSearchResults!$L$1:$L$100, 0), MATCH(F$2, REDBOOKSearchResults!$1:$1, 0)) -> 28s ea
A32: =REDBOOKSearchResults!G37 -> 44197 | B32: =REDBOOKSearchResults!H37 -> 956.81286 | C32: =REDBOOKSearchResults!I37 -> 4.5 | D32: =REDBOOKSearchResults!J37 -> 59572-0405-28 | E32: =INDEX(REDBOOKSearchResults!$N$2:$N$13, MATCH(D32, REDBOOKSearchResults!$L$2:$L$13, 0)) -> 5 mg | F32: =INDEX(REDBOOKSearchResults!$A$1:$AK$100, MATCH($D32, REDBOOKSearchResults!$L$1:$L$100, 0), MATCH(F$2, REDBOOKSearchResults!$1:$1, 0)) -> 28s ea
A33: =REDBOOKSearchResults!G38 -> 43831 | B33: =REDBOOKSearchResults!H38 -> 915.61036 | C33: =REDBOOKSearchResults!I38 -> 6 | D33: =REDBOOKSearchResults!J38 -> 59572-0405-28 | E33: =INDEX(REDBOOKSearchResults!$N$2:$N$13, MATCH(D33, REDBOOKSearchResults!$L$2:$L$13, 0)) -> 5 mg | F33: =INDEX(REDBOOKSearchResults!$A$1:$AK$100, MATCH($D33, REDBOOKSearchResults!$L$1:$L$100, 0), MATCH(F$2, REDBOOKSearchResults!$1:$1, 0)) -> 28s ea
A34: =REDBOOKSearchResults!G39 -> 43468 | B34: =REDBOOKSearchResults!H39 -> 863.78321 | C34: =REDBOOKSearchResults!I39 -> 3.5 | D34: =REDBOOKSearchResults!J39 -> 59572-0405-28 | E34: =INDEX(REDBOOKSearchResults!$N$2:$N$13, MATCH(D34, REDBOOKSearchResults!$L$2:$L$13, 0)) -> 5 mg | F34: =INDEX(REDBOOKSearchResults!$A$1:$AK$100, MATCH($D34, REDBOOKSearchResults!$L$1:$L$100, 0), MATCH(F$2, REDBOOKSearchResults!$1:$1, 0)) -> 28s ea
A35: =REDBOOKSearchResults!G40 -> 43291 | B35: =REDBOOKSearchResults!H40 -> 834.57286 | C35: =REDBOOKSearchResults!I40 -> 5 | D35: =REDBOOKSearchResults!J40 -> 59572-0405-28 | E35: =INDEX(REDBOOKSearchResults!$N$2:$N$13, MATCH(D35, REDBOOKSearchResults!$L$2:$L$13, 0)) -> 5 mg | F35: =INDEX(REDBOOKSearchResults!$A$1:$AK$100, MATCH($D35, REDBOOKSearchResults!$L$1:$L$100, 0), MATCH(F$2, REDBOOKSearchResults!$1:$1, 0)) -> 28s ea
A36: =REDBOOKSearchResults!G41 -> 43028 | B36: =REDBOOKSearchResults!H41 -> 794.83179 | C36: =REDBOOKSearchResults!I41 -> 9 | D36: =REDBOOKSearchResults!J41 -> 59572-0405-28 | E36: =INDEX(REDBOOKSearchResults!$N$2:$N$13, MATCH(D36, REDBOOKSearchResults!$L$2:$L$13, 0)) -> 5 mg | F36: =INDEX(REDBOOKSearchResults!$A$1:$AK$100, MATCH($D36, REDBOOKSearchResults!$L$1:$L$100, 0), MATCH(F$2, REDBOOKSearchResults!$1:$1, 0)) -> 28s ea
A37: =REDBOOKSearchResults!G42 -> 42927 | B37: =REDBOOKSearchResults!H42 -> 729.20321 | C37: =REDBOOKSearchResults!I42 -> 1.8 | D37: =REDBOOKSearchResults!J42 -> 59572-0405-28 | E37: =INDEX(REDBOOKSearchResults!$N$2:$N$13, MATCH(D37, REDBOOKSearchResults!$L$2:$L$13, 0)) -> 5 mg | F37: =INDEX(REDBOOKSearchResults!$A$1:$AK$100, MATCH($D37, REDBOOKSearchResults!$L$1:$L$100, 0), MATCH(F$2, REDBOOKSearchResults!$1:$1, 0)) -> 28s ea
A38: =REDBOOKSearchResults!G43 -> 42746 | B38: =REDBOOKSearchResults!H43 -> 716.66143 | C38: =REDBOOKSearchResults!I43 -> 8 | D38: =REDBOOKSearchResults!J43 -> 59572-0405-28 | E38: =INDEX(REDBOOKSearchResults!$N$2:$N$13, MATCH(D38, REDBOOKSearchResults!$L$2:$L$13, 0)) -> 5 mg | F38: =INDEX(REDBOOKSearchResults!$A$1:$AK$100, MATCH($D38, REDBOOKSearchResults!$L$1:$L$100, 0), MATCH(F$2, REDBOOKSearchResults!$1:$1, 0)) -> 28s ea
A39: =REDBOOKSearchResults!G44 -> 42602 | B39: =REDBOOKSearchResults!H44 -> 663.57571 | C39: =REDBOOKSearchResults!I44 -> 3 | D39: =REDBOOKSearchResults!J44 -> 59572-0405-28 | E39: =INDEX(REDBOOKSearchResults!$N$2:$N$13, MATCH(D39, REDBOOKSearchResults!$L$2:$L$13, 0)) -> 5 mg | F39: =INDEX(REDBOOKSearchResults!$A$1:$AK$100, MATCH($D39, REDBOOKSearchResults!$L$1:$L$100, 0), MATCH(F$2, REDBOOKSearchResults!$1:$1, 0)) -> 28s ea
A40: =REDBOOKSearchResults!G45 -> 42439 | B40: =REDBOOKSearchResults!H45 -> 644.24821 | C40: =REDBOOKSearchResults!I45 -> 6.8 | D40: =REDBOOKSearchResults!J45 -> 59572-0405-28 | E40: =INDEX(REDBOOKSearchResults!$N$2:$N$13, MATCH(D40, REDBOOKSearchResults!$L$2:$L$13, 0)) -> 5 mg | F40: =INDEX(REDBOOKSearchResults!$A$1:$AK$100, MATCH($D40, REDBOOKSearchResults!$L$1:$L$100, 0), MATCH(F$2, REDBOOKSearchResults!$1:$1, 0)) -> 28s ea
A41: =REDBOOKSearchResults!G46 -> 42279 | B41: =REDBOOKSearchResults!H46 -> 603.22893 | C41: =REDBOOKSearchResults!I46 -> 4 | D41: =REDBOOKSearchResults!J46 -> 59572-0405-28 | E41: =INDEX(REDBOOKSearchResults!$N$2:$N$13, MATCH(D41, REDBOOKSearchResults!$L$2:$L$13, 0)) -> 5 mg | F41: =INDEX(REDBOOKSearchResults!$A$1:$AK$100, MATCH($D41, REDBOOKSearchResults!$L$1:$L$100, 0), MATCH(F$2, REDBOOKSearchResults!$1:$1, 0)) -> 28s ea
... A53: =REDBOOKSearchResults!G58 -> 39904 | B53: =REDBOOKSearchResults!H58 -> 324.07214 | C53: =REDBOOKSearchResults!I58 -> 0 | D53: =REDBOOKSearchResults!J58 -> 59572-0405-28 | E53: =INDEX(REDBOOKSearchResults!$N$2:$N$13, MATCH(D53, REDBOOKSearchResults!$L$2:$L$13, 0)) -> 5 mg | F53: =INDEX(REDBOOKSearchResults!$A$1:$AK$100, MATCH($D53, REDBOOKSearchResults!$L$1:$L$100, 0), MATCH(F$2, REDBOOKSearchResults!$1:$1, 0)) -> 28s ea
A54: =REDBOOKSearchResults!L35 -> 45474 | B54: =REDBOOKSearchResults!M35 -> 1069.861 | C54: =REDBOOKSearchResults!N35 -> 7 | D54: =REDBOOKSearchResults!O35 -> 59572-0420-21 | E54: =INDEX(REDBOOKSearchResults!$N$2:$N$13, MATCH(D54, REDBOOKSearchResults!$L$2:$L$13, 0)) -> 20 mg | F54: =INDEX(REDBOOKSearchResults!$A$1:$AK$100, MATCH($D54, REDBOOKSearchResults!$L$1:$L$100, 0), MATCH(F$2, REDBOOKSearchResults!$1:$1, 0)) -> 21s ea
A55: =REDBOOKSearchResults!L36 -> 44562 | B55: =REDBOOKSearchResults!M36 -> 999.87048 | C55: =REDBOOKSearchResults!N36 -> 4.5 | D55: =REDBOOKSearchResults!O36 -> 59572-0420-21 | E55: =INDEX(REDBOOKSearchResults!$N$2:$N$13, MATCH(D55, REDBOOKSearchResults!$L$2:$L$13, 0)) -> 20 mg | F55: =INDEX(REDBOOKSearchResults!$A$1:$AK$100, MATCH($D55, REDBOOKSearchResults!$L$1:$L$100, 0), MATCH(F$2, REDBOOKSearchResults!$1:$1, 0)) -> 21s ea
A56: =REDBOOKSearchResults!L37 -> 44197 | B56: =REDBOOKSearchResults!M37 -> 956.81381 | C56: =REDBOOKSearchResults!N37 -> 4.5 | D56: =REDBOOKSearchResults!O37 -> 59572-0420-21 | E56: =INDEX(REDBOOKSearchResults!$N$2:$N$13, MATCH(D56, REDBOOKSearchResults!$L$2:$L$13, 0)) -> 20 mg | F56: =INDEX(REDBOOKSearchResults!$A$1:$AK$100, MATCH($D56, REDBOOKSearchResults!$L$1:$L$100, 0), MATCH(F$2, REDBOOKSearchResults!$1:$1, 0)) -> 21s ea
A57: =REDBOOKSearchResults!L38 -> 43831 | B57: =REDBOOKSearchResults!M38 -> 915.61143 | C57: =REDBOOKSearchResults!N38 -> 6 | D57: =REDBOOKSearchResults!O38 -> 59572-0420-21 | E57: =INDEX(REDBOOKSearchResults!$N$2:$N$13, MATCH(D57, REDBOOKSearchResults!$L$2:$L$13, 0)) -> 20 mg | F57: =INDEX(REDBOOKSearchResults!$A$1:$AK$100, MATCH($D57, REDBOOKSearchResults!$L$1:$L$100, 0), MATCH(F$2, REDBOOKSearchResults!$1:$1, 0)) -> 21s ea
A58: =REDBOOKSearchResults!L39 -> 43468 | B58: =REDBOOKSearchResults!M39 -> 863.78476 | C58: =REDBOOKSearchResults!N39 -> 3.5 | D58: =REDBOOKSearchResults!O39 -> 59572-0420-21 | E58: =INDEX(REDBOOKSearchResults!$N$2:$N$13, MATCH(D58, REDBOOKSearchResults!$L$2:$L$13, 0)) -> 20 mg | F58: =INDEX(REDBOOKSearchResults!$A$1:$AK$100, MATCH($D58, REDBOOKSearchResults!$L$1:$L$100, 0), MATCH(F$2, REDBOOKSearchResults!$1:$1, 0)) -> 21s ea
A59: =REDBOOKSearchResults!L40 -> 43291 | B59: =REDBOOKSearchResults!M40 -> 834.57429 | C59: =REDBOOKSearchResults!N40 -> 5 | D59: =REDBOOKSearchResults!O40 -> 59572-0420-21 | E59: =INDEX(REDBOOKSearchResults!$N$2:$N$13, MATCH(D59, REDBOOKSearchResults!$L$2:$L$13, 0)) -> 20 mg | F59: =INDEX(REDBOOKSearchResults!$A$1:$AK$100, MATCH($D59, REDBOOKSearchResults!$L$1:$L$100, 0), MATCH(F$2, REDBOOKSearchResults!$1:$1, 0)) -> 21s ea
A60: =REDBOOKSearchResults!L41 -> 43028 | B60: =REDBOOKSearchResults!M41 -> 794.83238 | C60: =REDBOOKSearchResults!N41 -> 9 | D60: =REDBOOKSearchResults!O41 -> 59572-0420-21 | E60: =INDEX(REDBOOKSearchResults!$N$2:$N$13, MATCH(D60, REDBOOKSearchResults!$L$2:$L$13, 0)) -> 20 mg | F60: =INDEX(REDBOOKSearchResults!$A$1:$AK$100, MATCH($D60, REDBOOKSearchResults!$L$1:$L$100, 0), MATCH(F$2, REDBOOKSearchResults!$1:$1, 0)) -> 21s ea
A61: =REDBOOKSearchResults!L42 -> 42927 | B61: =REDBOOKSearchResults!M42 -> 729.20381 | C61: =REDBOOKSearchResults!N42 -> 1.7 | D61: =REDBOOKSearchResults!O42 -> 59572-0420-21 | E61: =INDEX(REDBOOKSearchResults!$N$2:$N$13, MATCH(D61, REDBOOKSearchResults!$L$2:$L$13, 0)) -> 20 mg | F61: =INDEX(REDBOOKSearchResults!$A$1:$AK$100, MATCH($D61, REDBOOKSearchResults!$L$1:$L$100, 0), MATCH(F$2, REDBOOKSearchResults!$1:$1, 0)) -> 21s ea
A62: =REDBOOKSearchResults!L43 -> 42746 | B62: =REDBOOKSearchResults!M43 -> 716.66238 | C62: =REDBOOKSearchResults!N43 -> 8 | D62: =REDBOOKSearchResults!O43 -> 59572-0420-21 | E62: =INDEX(REDBOOKSearchResults!$N$2:$N$13, MATCH(D62, REDBOOKSearchResults!$L$2:$L$13, 0)) -> 20 mg | F62: =INDEX(REDBOOKSearchResults!$A$1:$AK$100, MATCH($D62, REDBOOKSearchResults!$L$1:$L$100, 0), MATCH(F$2, REDBOOKSearchResults!$1:$1, 0)) -> 21s ea
A63: =REDBOOKSearchResults!L44 -> 42602 | B63: =REDBOOKSearchResults!M44 -> 663.57619 | C63: =REDBOOKSearchResults!N44 -> 3 | D63: =REDBOOKSearchResults!O44 -> 59572-0420-21 | E63: =INDEX(REDBOOKSearchResults!$N$2:$N$13, MATCH(D63, REDBOOKSearchResults!$L$2:$L$13, 0)) -> 20 mg | F63: =INDEX(REDBOOKSearchResults!$A$1:$AK$100, MATCH($D63, REDBOOKSearchResults!$L$1:$L$100, 0), MATCH(F$2, REDBOOKSearchResults!$1:$1, 0)) -> 21s ea
A64: =REDBOOKSearchResults!L45 -> 42439 | B64: =REDBOOKSearchResults!M45 -> 644.24857 | C64: =REDBOOKSearchResults!N45 -> 6.8 | D64: =REDBOOKSearchResults!O45 -> 59572-0420-21 | E64: =INDEX(REDBOOKSearchResults!$N$2:$N$13, MATCH(D64, REDBOOKSearchResults!$L$2:$L$13, 0)) -> 20 mg | F64: =INDEX(REDBOOKSearchResults!$A$1:$AK$100, MATCH($D64, REDBOOKSearchResults!$L$1:$L$100, 0), MATCH(F$2, REDBOOKSearchResults!$1:$1, 0)) -> 21s ea
A65: =REDBOOKSearchResults!L46 -> 42279 | B65: =REDBOOKSearchResults!M46 -> 603.22905 | C65: =REDBOOKSearchResults!N46 -> 4 | D65: =REDBOOKSearchResults!O46 -> 59572-0420-21 | E65: =INDEX(REDBOOKSearchResults!$N$2:$N$13, MATCH(D65, REDBOOKSearchResults!$L$2:$L$13, 0)) -> 20 mg | F65: =INDEX(REDBOOKSearchResults!$A$1:$AK$100, MATCH($D65, REDBOOKSearchResults!$L$1:$L$100, 0), MATCH(F$2, REDBOOKSearchResults!$1:$1, 0)) -> 21s ea
...

Sheet Sheet3
A3: Sum of Unit | B3: Column Labels
A4: Row Labels | B4: 59572-0402-00 | C4: 59572-0402-28 | D4: 59572-0405-00 | E4: 59572-0405-28 | F4: 59572-0410-00 | G4: 59572-0410-28 | H4: 59572-0415-00 | I4: 59572-0415-21 | J4: 59572-0420-00 | K4: 59572-0420-21 | L4: 59572-0425-00 | M4: 59572-0425-21 | N4: Grand Total | O4: Av | P4: Max | Q4: Min | R4: Range | S4: Pos Error | T4: Neg error
A5: 38715 | D5: 258 | F5: 270 | N5: 528 | O5: =AVERAGE(B5:M5) -> 264 | P5: =MAX(B5:M5) -> 270 | Q5: =MIN(B5:M5) -> 258 | R5: =P5-Q5 -> 12 | S5: =P5-O5 -> 6 | T5: =O5-Q5 -> 6
A6: 38898 | H6: 336 | I6: 336 | L6: 354 | N6: 1026 | O6: =AVERAGE(B6:M6) -> 342 | P6: =MAX(B6:M6) -> 354 | Q6: =MIN(B6:M6) -> 336 | R6: =P6-Q6 -> 18 | S6: =P6-O6 -> 12 | T6: =O6-Q6 -> 6
A7: 39085 | D7: 283.542 | F7: 296.73 | H7: 346.08 | I7: 346.08 | L7: 364.62 | N7: 1637.052 | O7: =AVERAGE(B7:M7) -> 327.4104 | P7: =MAX(B7:M7) -> 364.62 | Q7: =MIN(B7:M7) -> 283.542 | R7: =P7-Q7 -> 81.078 | S7: =P7-O7 -> 37.2096 | T7: =O7-Q7 -> 43.8684
A8: 39451 | D8: 311.6127 | F8: 326.1062 | H8: 363.0379 | I8: 363.03762 | L8: 377.3818 | N8: 1741.1762 | O8: =AVERAGE(B8:M8) -> 348.23524 | P8: =MAX(B8:M8) -> 377.3818 | Q8: =MIN(B8:M8) -> 311.6127 | R8: =P8-Q8 -> 65.7691 | S8: =P8-O8 -> 29.146556 | T8: =O8-Q8 -> 36.622544
A9: 39787 | D9: 324.0771 | F9: 339.1505 | H9: 377.5595 | I9: 377.55952 | L9: 392.477 | N9: 1810.8236 | O9: =AVERAGE(B9:M9) -> 362.16472 | P9: =MAX(B9:M9) -> 392.477 | Q9: =MIN(B9:M9) -> 324.0771 | R9: =P9-Q9 -> 68.3999 | S9: =P9-O9 -> 30.312276 | T9: =O9-Q9 -> 38.087624
A10: 39904 | E10: 324.07214 | G10: 339.15607 | M10: 392.4719 | N10: 1055.7001 | O10: =AVERAGE(B10:M10) -> 351.90004 | P10: =MAX(B10:M10) -> 392.4719 | Q10: =MIN(B10:M10) -> 324.07214 | R10: =P10-Q10 -> 68.39976 | S10: =P10-O10 -> 40.571863 | T10: =O10-Q10 -> 27.827897
A11: 39939 | D11: 356.2904 | E11: 356.28821 | F11: 372.8621 | G11: 372.86821 | H11: 388.6597 | I11: 388.65952 | N11: 2235.6281 | O11: =AVERAGE(B11:M11) -> 372.60469 | P11: =MAX(B11:M11) -> 388.6597 | Q11: =MIN(B11:M11) -> 356.28821 | R11: =P11-Q11 -> 32.37149 | S11: =P11-O11 -> 16.05501 | T11: =O11-Q11 -> 16.31648
A12: 40183 | D12: 388.0003 | E12: 387.99786 | F12: 406.0468 | G12: 406.04929 | H12: 407.7041 | I12: 407.70381 | L12: 411.7084 | M12: 411.70286 | N12: 3226.9134 | O12: =AVERAGE(B12:M12) -> 403.36418 | P12: =MAX(B12:M12) -> 411.7084 | Q12: =MIN(B12:M12) -> 387.99786 | R12: =P12-Q12 -> 23.71054 | S12: =P12-O12 -> 8.3442225 | T12: =O12-Q12 -> 15.366317
A13: 40523 | D13: 415.1557 | E13: 415.15571 | F13: 422.2858 | G13: 422.28571 | H13: 424.008 | I13: 424.0081 | L13: 428.1763 | M13: 428.17667 | N13: 3379.252 | O13: =AVERAGE(B13:M13) -> 422.4065 | P13: =MAX(B13:M13) -> 428.17667 | Q13: =MIN(B13:M13) -> 415.1557 | R13: =P13-Q13 -> 13.02097 | S13: =P13-O13 -> 5.7701713 | T13: =O13-Q13 -> 7.2507987
A14: 40876 | D14: 440.0651 | E14: 440.06536 | F14: 447.6229 | G14: 447.62286 | H14: 449.4485 | I14: 449.44857 | L14: 453.8669 | M14: 453.86762 | N14: 3582.0078 | O14: =AVERAGE(B14:M14) -> 447.75098 | P14: =MAX(B14:M14) -> 453.86762 | Q14: =MIN(B14:M14) -> 440.0651 | R14: =P14-Q14 -> 13.80252 | S14: =P14-O14 -> 6.1166437 | T14: =O14-Q14 -> 7.6858763
A15: 41015 | B15: 440.0651 | C15: 440.06536 | N15: 880.13046 | O15: =AVERAGE(B15:M15) -> 440.06523 | P15: =MAX(B15:M15) -> 440.06536 | Q15: =MIN(B15:M15) -> 440.0651 | R15: =P15-Q15 -> 0.00026 | S15: =P15-O15 -> 0.00013 | T15: =O15-Q15 -> 0.00013
A16: 41214 | B16: 466.4691 | C16: 466.46929 | D16: 466.4691 | E16: 466.46929 | F16: 474.4802 | G16: 474.48 | H16: 476.4154 | I16: 476.41524 | L16: 481.0988 | M16: 481.09952 | N16: 4729.8659 | O16: =AVERAGE(B16:M16) -> 472.98659 | P16: =MAX(B16:M16) -> 481.09952 | Q16: =MIN(B16:M16) -> 466.4691 | R16: =P16-Q16 -> 14.63042 | S16: =P16-O16 -> 8.112926 | T16: =O16-Q16 -> 6.517494
A17: 41363 | B17: 480.4631 | C17: 480.46321 | D17: 480.4631 | E17: 480.46321 | F17: 488.7146 | G17: 488.71464 | H17: 490.7079 | I17: 490.7081 | L17: 495.5318 | M17: 495.53238 | N17: 4871.762 | O17: =AVERAGE(B17:M17) -> 487.1762 | P17: =MAX(B17:M17) -> 495.53238 | Q17: =MIN(B17:M17) -> 480.4631 | R17: =P17-Q17 -> 15.06928 | S17: =P17-O17 -> 8.356176 | T17: =O17-Q17 -> 6.713104
A18: 41443 | J18: 495.5318 | K18: 495.53238 | N18: 991.06418 | O18: =AVERAGE(B18:M18) -> 495.53209 | P18: =MAX(B18:M18) -> 495.53238 | Q18: =MIN(B18:M18) -> 495.5318 | R18: =P18-Q18 -> 0.00058 | S18: =P18-O18 -> 0.00029 | T18: =O18-Q18 -> 0.00029
A19: 41548 | B19: 494.877 | C19: 494.87714 | D19: 494.877 | E19: 494.87714 | F19: 503.3761 | G19: 503.37607 | H19: 505.4291 | I19: 505.42905 | J19: 510.3978 | K19: 510.3981 | L19: 510.3978 | M19: 510.3981 | N19: 6038.7104 | O19: =AVERAGE(B19:M19) -> 503.22587 | P19: =MAX(B19:M19) -> 510.3981 | Q19: =MIN(B19:M19) -> 494.877 | R19: =P19-Q19 -> 15.5211 | S19: =P19-O19 -> 7.1722333 | T19: =O19-Q19 -> 8.3488667
A20: 41704 | B20: 514.6721 | C20: 514.67214 | D20: 514.6721 | E20: 514.67214 | F20: 523.5112 | G20: 523.51107 | H20: 525.6462 | I20: 525.64619 | J20: 530.8138 | K20: 530.81429 | L20: 530.8138 | M20: 530.81429 | N20: 6280.2593 | O20: =AVERAGE(B20:M20) -> 523.35494 | P20: =MAX(B20:M20) -> 530.81429 | Q20: =MIN(B20:M20) -> 514.6721 | R20: =P20-Q20 -> 16.14219 | S20: =P20-O20 -> 7.4593467 | T20: =O20-Q20 -> 8.6828433
A21: 41885 | B21: 546.732 | C21: 546.73214 | D21: 546.732 | E21: 546.73214 | F21: 546.732 | G21: 546.73214 | H21: 546.732 | I21: 546.7319 | J21: 546.732 | K21: 546.7319 | L21: 546.732 | M21: 546.7319 | N21: 6560.7841 | O21: =AVERAGE(B21:M21) -> 546.73201 | P21: =MAX(B21:M21) -> 546.73214 | Q21: =MIN(B21:M21) -> 546.7319 | R21: =P21-Q21 -> 0.00024 | S21: =P21-O21 -> 0.00013 | T21: =O21-Q21 -> 0.00011
A22: 41996 | B22: 563.1339 | C22: 563.13393 | D22: 563.1339 | E22: 563.13393 | F22: 563.1339 | G22: 563.13393 | H22: 563.1339 | I22: 563.13381 | J22: 563.1339 | K22: 563.13381 | L22: 563.1339 | M22: 563.13381 | N22: 6757.6066 | O22: =AVERAGE(B22:M22) -> 563.13389 | P22: =MAX(B22:M22) -> 563.13393 | Q22: =MIN(B22:M22) -> 563.13381 | R22: =P22-Q22 -> 0.00012 | S22: =P22-O22 -> 4.5e-05 | T22: =O22-Q22 -> 7.5e-05
A23: 42180 | B23: 580.0279 | C23: 580.02786 | D23: 580.0279 | E23: 580.02786 | F23: 580.0279 | G23: 580.02786 | H23: 580.0279 | I23: 580.0281 | J23: 580.0279 | K23: 580.0281 | L23: 580.0279 | M23: 580.0281 | N23: 6960.3353 | O23: =AVERAGE(B23:M23) -> 580.02794 | P23: =MAX(B23:M23) -> 580.0281 | Q23: =MIN(B23:M23) -> 580.02786 | R23: =P23-Q23 -> 0.00024 | S23: =P23-O23 -> 0.00016 | T23: =O23-Q23 -> 8e-05
A24: 42279 | B24: 603.2291 | C24: 603.22893 | D24: 603.2291 | E24: 603.22893 | F24: 603.2291 | G24: 603.22893 | H24: 603.2291 | I24: 603.22905 | J24: 603.2291 | K24: 603.22905 | L24: 603.2291 | M24: 603.22905 | N24: 7238.7485 | O24: =AVERAGE(B24:M24) -> 603.22905 | P24: =MAX(B24:M24) -> 603.2291 | Q24: =MIN(B24:M24) -> 603.22893 | R24: =P24-Q24 -> 0.00017 | S24: =P24-O24 -> 5.5e-05 | T24: =O24-Q24 -> 0.000115
A25: 42439 | B25: 644.2487 | C25: 644.24821 | D25: 644.2487 | E25: 644.24821 | F25: 644.2487 | G25: 644.24821 | H25: 644.2487 | I25: 644.24857 | J25: 644.2487 | K25: 644.24857 | L25: 644.2487 | M25: 644.24857 | N25: 7730.9825 | O25: =AVERAGE(B25:M25) -> 644.24854 | P25: =MAX(B25:M25) -> 644.2487 | Q25: =MIN(B25:M25) -> 644.24821 | R25: =P25-Q25 -> 0.00049 | S25: =P25-O25 -> 0.000155 | T25: =O25-Q25 -> 0.000335
A26: 42602 | B26: 663.5762 | C26: 663.57571 | D26: 663.5762 | E26: 663.57571 | F26: 663.5762 | G26: 663.57571 | H26: 663.5762 | I26: 663.57619 | J26: 663.5762 | K26: 663.57619 | L26: 663.5762 | M26: 663.57619 | N26: 7962.9129 | O26: =AVERAGE(B26:M26) -> 663.57607 | P26: =MAX(B26:M26) -> 663.5762 | Q26: =MIN(B26:M26) -> 663.57571 | R26: =P26-Q26 -> 0.00049 | S26: =P26-O26 -> 0.000125 | T26: =O26-Q26 -> 0.000365
A27: 42746 | B27: 716.6622 | C27: 716.66143 | D27: 716.6622 | E27: 716.66143 | F27: 716.6622 | G27: 716.66143 | H27: 716.6622 | I27: 716.66238 | J27: 716.6622 | K27: 716.66238 | L27: 716.6622 | M27: 716.66238 | N27: 8599.9446 | O27: =AVERAGE(B27:M27) -> 716.66205 | P27: =MAX(B27:M27) -> 716.66238 | Q27: =MIN(B27:M27) -> 716.66143 | R27: =P27-Q27 -> 0.00095 | S27: =P27-O27 -> 0.0003275 | T27: =O27-Q27 -> 0.0006225
A28: 42927 | B28: 729.2038 | C28: 729.20321 | D28: 729.2038 | E28: 729.20321 | F28: 729.2038 | G28: 729.20321 | H28: 729.2038 | I28: 729.20381 | J28: 729.2038 | K28: 729.20381 | L28: 729.2038 | M28: 729.20381 | N28: 8750.4439 | O28: =AVERAGE(B28:M28) -> 729.20365 | P28: =MAX(B28:M28) -> 729.20381 | Q28: =MIN(B28:M28) -> 729.20321 | R28: =P28-Q28 -> 0.0006 | S28: =P28-O28 -> 0.000155 | T28: =O28-Q28 -> 0.000445
A29: 43028 | B29: 794.8321 | C29: 794.83179 | D29: 794.8321 | E29: 794.83179 | F29: 794.8321 | G29: 794.83179 | H29: 794.8321 | I29: 794.83238 | J29: 794.8321 | K29: 794.83238 | L29: 794.8321 | M29: 794.83238 | N29: 9537.9851 | O29: =AVERAGE(B29:M29) -> 794.83209 | P29: =MAX(B29:M29) -> 794.83238 | Q29: =MIN(B29:M29) -> 794.83179 | R29: =P29-Q29 -> 0.00059 | S29: =P29-O29 -> 0.0002875 | T29: =O29-Q29 -> 0.0003025
A30: 43291 | B30: 834.5738 | C30: 834.57286 | D30: 834.5738 | E30: 834.57286 | F30: 834.5738 | G30: 834.57286 | H30: 834.5738 | I30: 834.57429 | J30: 834.5738 | K30: 834.57429 | L30: 834.5738 | M30: 834.57429 | N30: 10014.884 | O30: =AVERAGE(B30:M30) -> 834.57369 | P30: =MAX(B30:M30) -> 834.57429 | Q30: =MIN(B30:M30) -> 834.57286 | R30: =P30-Q30 -> 0.00143 | S30: =P30-O30 -> 0.0006025 | T30: =O30-Q30 -> 0.0008275
... A35: 45474 | B35: 1069.8608 | C35: 1069.86 | D35: 1069.8608 | E35: 1069.86 | F35: 1069.8608 | G35: 1069.86 | H35: 1069.8608 | I35: 1069.861 | J35: 1069.8608 | K35: 1069.861 | L35: 1069.8608 | M35: 1069.861 | N35: 12838.328 | O35: =AVERAGE(B35:M35) -> 1069.8606 | P35: =MAX(B35:M35) -> 1069.861 | Q35: =MIN(B35:M35) -> 1069.86 | R35: =P35-Q35 -> 0.00095 | S35: =P35-O35 -> 0.0003125 | T35: =O35-Q35 -> 0.0006375
A36: Grand Total | B36: 13878.705 | C36: 13878.699 | D36: 16215.383 | E36: 15362.213 | F36: 16353.045 | G36: 15460.216 | H36: 16572.855 | I36: 16572.858 | J36: 13018.902 | K36: 13018.907 | L36: 16282.231 | M36: 15186.225 | N36: 181800.24 | P36: =MAX(B36:M36) -> 16572.858 | Q36: =MIN(B36:M36) -> 13018.902 | R36: =P36-Q36 -> 3553.9559 | S36: =P36-O36 -> 16572.858 | T36: =O36-Q36 -> -13018.902
A42: Date | B42: Average | C42: Pos Error | D42: Neg Error | E42: Year | F42: Avg Cost/Unit
A43: =A5 -> 38715 | B43: =O5 -> 264 | C43: =S5 -> 6 | D43: =T5 -> 6 | E43: 2010 | F43: 350.27887
A44: =A6 -> 38898 | B44: =O6 -> 342 | C44: =S6 -> 12 | D44: =T6 -> 6 | E44: 2011 | F44: 366.82979
A45: =A7 -> 39085 | B45: =O7 -> 327.4104 | C45: =S7 -> 37.2096 | D45: =T7 -> 43.8684 | E45: 2012 | F45: 389.28908
A46: =A8 -> 39451 | B46: =O8 -> 348.23524 | C46: =S8 -> 29.146556 | D46: =T8 -> 36.622544 | E46: 2013 | F46: 418.39983
A47: =A9 -> 39787 | B47: =O9 -> 362.16472 | C47: =S9 -> 30.312276 | D47: =T9 -> 38.087624 | E47: 2014 | F47: 450.96504
A48: =A10 -> 39904 | B48: =O10 -> 351.90004 | C48: =S10 -> 40.571863 | D48: =T10 -> 27.827897 | E48: 2015 | F48: 489.91125
A49: =A11 -> 39939 | B49: =O11 -> 372.60469 | C49: =S11 -> 16.05501 | D49: =T11 -> 16.31648 | E49: 2016 | F49: 543.5902
A50: =A12 -> 40183 | B50: =O12 -> 403.36418 | C50: =S12 -> 8.3442225 | D50: =T12 -> 15.366317 | E50: 2017 | F50: 626.94005
A51: =A13 -> 40523 | B51: =O13 -> 422.4065 | C51: =S13 -> 5.7701713 | D51: =T13 -> 7.2507987 | E51: 2018 | F51: 697.35425
...

Sheet Sheet2
A1: Effective Date | B1: Unit | C1: Identifier | D1: Dosage | E1: Package Size
A2: 45474 | B2: 1069.8608 | C2: 59572-0405-00 | D2: 5 mg | E2: 100s ea
A3: 44562 | B3: 999.8699 | C3: 59572-0405-00 | D3: 5 mg | E3: 100s ea
A4: 44197 | B4: 956.8133 | C4: 59572-0405-00 | D4: 5 mg | E4: 100s ea
A5: 43831 | B5: 915.6108 | C5: 59572-0405-00 | D5: 5 mg | E5: 100s ea
A6: 43468 | B6: 863.7838 | C6: 59572-0405-00 | D6: 5 mg | E6: 100s ea
A7: 43291 | B7: 834.5738 | C7: 59572-0405-00 | D7: 5 mg | E7: 100s ea
A8: 43028 | B8: 794.8321 | C8: 59572-0405-00 | D8: 5 mg | E8: 100s ea
A9: 42927 | B9: 729.2038 | C9: 59572-0405-00 | D9: 5 mg | E9: 100s ea
A10: 42746 | B10: 716.6622 | C10: 59572-0405-00 | D10: 5 mg | E10: 100s ea
A11: 42602 | B11: 663.5762 | C11: 59572-0405-00 | D11: 5 mg | E11: 100s ea
A12: 42439 | B12: 644.2487 | C12: 59572-0405-00 | D12: 5 mg | E12: 100s ea
A13: 42279 | B13: 603.2291 | C13: 59572-0405-00 | D13: 5 mg | E13: 100s ea
... A282: 39904 | B282: 339.15607 | C282: 59572-0410-28 | D282: 10 mg | E282: 28s ea

Sheet Sheet4
A1: Effective Date | B1: Unit | C1: Avg Cost/Unit | F1: Year | G1: Avg Cost/Unit
A2: 38715 | B2: 264 | F2: 40543 | G2: ='[1]Medicare Cost'!B23 -> 350.27887
A3: 38898 | B3: 342 | F3: =F2+365 -> 40908 | G3: ='[1]Medicare Cost'!B24 -> 366.82979
A4: 39085 | B4: 327.4104 | F4: 41274 | G4: ='[1]Medicare Cost'!B25 -> 389.28908
A5: 39451 | B5: 348.23524 | F5: =F4+365 -> 41639 | G5: ='[1]Medicare Cost'!B26 -> 418.39983
A6: 39787 | B6: 362.16472 | F6: =F5+365 -> 42004 | G6: ='[1]Medicare Cost'!B27 -> 450.96504
A7: 39904 | B7: 351.90004 | F7: =F6+365 -> 42369 | G7: ='[1]Medicare Cost'!B28 -> 489.91125
A8: 39939 | B8: 372.60469 | F8: 42735 | G8: ='[1]Medicare Cost'!B29 -> 543.5902
A9: 40183 | B9: 403.36418 | C9: =G2 -> 350.27887 | F9: =F8+365 -> 43100 | G9: ='[1]Medicare Cost'!B30 -> 626.94005
A10: 40523 | B10: 422.4065 | C10: =G2 -> 350.27887 | F10: =F9+365 -> 43465 | G10: ='[1]Medicare Cost'!B31 -> 697.35425
A11: 40876 | B11: 447.75098 | C11: =G3 -> 366.82979 | F11: =F10+365 -> 43830 | G11: ='[1]Medicare Cost'!B32 -> 745.5885
A12: 41015 | B12: 440.06523 | C12: =G4 -> 389.28908 | F12: =F11+366 -> 44196 | G12: ='[1]Medicare Cost'!B33 -> 794.32803
A13: 41214 | B13: 472.98659 | C13: =G4 -> 389.28908 | F13: =F12+365 -> 44561 | G13: ='[1]Medicare Cost'!B34 -> 840.17444
A14: 41363 | B14: 487.1762 | C14: =G5 -> 418.39983 | F14: =F13+365 -> 44926 | G14: ='[1]Medicare Cost'!B35 -> 883.09618
A15: 41443 | B15: 495.53209 | C15: =G5 -> 418.39983 | F15: =F14+365 -> 45291 | G15: ='[1]Medicare Cost'!B36 -> 878.2122
A16: 41548 | B16: 503.22587 | C16: =G5 -> 418.39983 | F16: =F2-364 -> 40179 | G16: =G2 -> 350.27887
A17: 41704 | B17: 523.35494 | C17: =G6 -> 450.96504 | F17: =F3-364 -> 40544 | G17: =G3 -> 366.82979
A18: 41885 | B18: 546.73201 | C18: =G6 -> 450.96504 | F18: =F4-365 -> 40909 | G18: =G4 -> 389.28908
A19: 41996 | B19: 563.13389 | C19: =G6 -> 450.96504 | F19: =F5-364 -> 41275 | G19: =G5 -> 418.39983
A20: 42180 | B20: 580.02794 | C20: =G7 -> 489.91125 | F20: =F6-364 -> 41640 | G20: =G6 -> 450.96504
A21: 42279 | B21: 603.22905 | C21: =G7 -> 489.91125 | F21: =F7-364 -> 42005 | G21: =G7 -> 489.91125
A22: 42439 | B22: 644.24854 | C22: =G8 -> 543.5902 | F22: =F8-365 -> 42370 | G22: =G8 -> 543.5902
A23: 42602 | B23: 663.57607 | C23: =G8 -> 543.5902 | F23: =F9-364 -> 42736 | G23: =G9 -> 626.94005
A24: 42746 | B24: 716.66205 | C24: =G9 -> 626.94005 | F24: =F10-364 -> 43101 | G24: =G10 -> 697.35425
A25: 42927 | B25: 729.20365 | C25: =G9 -> 626.94005 | F25: =F11-364 -> 43466 | G25: =G11 -> 745.5885
A26: 43028 | B26: 794.83209 | C26: =G9 -> 626.94005 | F26: =F12-365 -> 43831 | G26: =G12 -> 794.32803
A27: 43291 | B27: 834.57369 | C27: =G10 -> 697.35425 | F27: =F13-364 -> 44197 | G27: =G13 -> 840.17444
A28: 43468 | B28: 863.78389 | C28: =G11 -> 745.5885 | F28: =F14-364 -> 44562 | G28: =G14 -> 883.09618
A29: 43831 | B29: 915.61085 | C29: =G12 -> 794.32803 | F29: =F15-364 -> 44927 | G29: =G15 -> 878.2122
A30: 44197 | B30: 956.81332 | C30: =G13 -> 840.17444
A31: 44562 | B31: 999.86989 | C31: =G14 -> 883.09618
A32: 45474 | B32: 1069.8606
A33: 40543 | C33: 350.27887
A34: 40908 | C34: 366.82979
A35: 41274 | C35: 389.28908
A36: 41639 | C36: 418.39983
A37: 42004 | C37: 450.96504
A38: 42369 | C38: 489.91125
A39: 42735 | C39: 543.5902
A40: 43100 | C40: 626.94005
...

Sheet Sheet1
B1: Effective Date | C1: Unit | D1: % Change | E1: Identifier | F1: Price Paid since last price hike | J1: Effective Date | K1: Unit
A2: 1 | B2: 38715 | C2: 258 | D2: 0 | E2: 59572-0405-00 | I2: 1 | J2: 38898 | K2: 354
A3: =B3-B$2 -> 370 | B3: 39085 | C3: 283.542 | D3: 9.9 | E3: 59572-0405-00 | F3: =(A3-A2)*C2 -> 95202 | I3: =J3-J$2 -> 187 | J3: 39085 | K3: 364.62 | L3: =(I3-I2)*K2*0.75 -> 49383
A4: =B4-B$2 -> 736 | B4: 39451 | C4: 311.6127 | D4: 9.9 | E4: 59572-0405-00 | F4: =(A4-A3)*C3 -> 103776.37 | I4: =J4-J$2 -> 553 | J4: 39451 | K4: 377.3818 | L4: =(I4-I3)*K3*0.75 -> 100088.19
A5: =B5-B$2 -> 1072 | B5: 39787 | C5: 324.0771 | D5: 4 | E5: 59572-0405-00 | F5: =(A5-A4)*C4 -> 104701.87 | I5: =J5-J$2 -> 889 | J5: 39787 | K5: 392.477 | L5: =(I5-I4)*K4*0.75 -> 95100.214
A6: =B6-B$2 -> 1224 | B6: 39939 | C6: 356.2904 | D6: 9.9 | E6: 59572-0405-00 | F6: =(A6-A5)*C5 -> 49259.719 | I6: =J6-J$2 -> 1285 | J6: 40183 | K6: 411.7084 | L6: =(I6-I5)*K5*0.75 -> 116565.67
A7: =B7-B$2 -> 1468 | B7: 40183 | C7: 388.0003 | D7: 8.9 | E7: 59572-0405-00 | F7: =(A7-A6)*C6 -> 86934.858 | I7: =J7-J$2 -> 1625 | J7: 40523 | K7: 428.1763 | L7: =(I7-I6)*K6*0.75 -> 104985.64
A8: =B8-B$2 -> 1808 | B8: 40523 | C8: 415.1557 | D8: 7 | E8: 59572-0405-00 | F8: =(A8-A7)*C7 -> 131920.1 | I8: =J8-J$2 -> 1978 | J8: 40876 | K8: 453.8669 | L8: =(I8-I7)*K7*0.75 -> 113359.68
A9: =B9-B$2 -> 2161 | B9: 40876 | C9: 440.0651 | D9: 6 | E9: 59572-0405-00 | F9: =(A9-A8)*C8 -> 146549.96 | I9: =J9-J$2 -> 2316 | J9: 41214 | K9: 481.0988 | L9: =(I9-I8)*K8*0.75 -> 115055.26
A10: =B10-B$2 -> 2499 | B10: 41214 | C10: 466.4691 | D10: 6 | E10: 59572-0405-00 | F10: =(A10-A9)*C9 -> 148742 | I10: =J10-J$2 -> 2465 | J10: 41363 | K10: 495.5318 | L10: =(I10-I9)*K9*0.75 -> 53762.791
A11: =B11-B$2 -> 2648 | B11: 41363 | C11: 480.4631 | D11: 3 | E11: 59572-0405-00 | F11: =(A11-A10)*C10 -> 69503.896 | I11: =J11-J$2 -> 2650 | J11: 41548 | K11: 510.3978 | L11: =(I11-I10)*K10*0.75 -> 68755.037
A12: =B12-B$2 -> 2833 | B12: 41548 | C12: 494.877 | D12: 3 | E12: 59572-0405-00 | F12: =(A12-A11)*C11 -> 88885.674 | I12: =J12-J$2 -> 2806 | J12: 41704 | K12: 530.8138 | L12: =(I12-I11)*K11*0.75 -> 59716.543
A13: =B13-B$2 -> 2989 | B13: 41704 | C13: 514.6721 | D13: 4 | E13: 59572-0405-00 | F13: =(A13-A12)*C12 -> 77200.812 | I13: =J13-J$2 -> 2987 | J13: 41885 | K13: 546.732 | L13: =(I13-I12)*K12*0.75 -> 72057.973
A14: =B14-B$2 -> 3170 | B14: 41885 | C14: 546.732 | D14: 6.2 | E14: 59572-0405-00 | F14: =(A14-A13)*C13 -> 93155.65 | I14: =J14-J$2 -> 3098 | J14: 41996 | K14: 563.1339 | L14: =(I14-I13)*K13*0.75 -> 45515.439
... A27: =B27-B$2 -> 5847 | B27: 44562 | C27: 999.8699 | D27: 4.5 | E27: 59572-0405-00 | F27: =(A27-A26)*C26 -> 349236.85 | I27: =J27-J$2 -> 6576 | J27: 45474 | K27: 1069.8608 | L27: =(I27-I26)*K26*0.75 -> 683911.01
A28: =B28-B$2 -> 6759 | B28: 45474 | C28: 1069.8608 | D28: 7 | E28: 59572-0405-00 | F28: =(A28-A27)*C27 -> 911881.35 | L28: =SUM(L3:L27) -> 3190371.4
F29: =SUM(F3:F28) -> 4184554.9 | G29: =F29*0.75 -> 3138416.1
