Workbook

Sheet REDBOOK
C1: RED BOOK AWP Price History
C2: Product Name: REVLIMID
C3: Code: NDC
C4: Identifier: 59572-0405-00
C5: Other Info: | D5: 5mg, Package Size 100s
C8: Effective Date | D8: Unit | E8: % Change | F8: Has The Price Ever Declined | G8: Predicted | H8: Was It Supposed To Drop | I8: Derivative | J8: Scheduled Day For This Price Point | K8: Scheduled Date | L8: How Long Since Last Increase | M8: Distance Between Predicted and Set Price | N8: Distance Between Expected Date and Announced Date | O8: Price Paid By A Patient
A9: =A10+1 -> 27 | B9: =C9-C$35 -> 6759 | C9: 45474 | D9: 1069.8608 | E9: 7 | F9: =IF(D9<D10,TRUE,FALSE) -> FALSE | G9: {=SUMPRODUCT(B9^{5,4,3,2,1,0}, LINEST(D$9:D$35,B$9:B$35^{1,2,3,4,5}))} -> 1064.0941 | H9: =IF(G9<G10,TRUE,FALSE) -> FALSE | I9: =(5*G$39*(B9^4))+(4*H$39*(B9^3))+(3*I$39*(B9^2))+(2*J$39*(B9^1))+(1*K$39*(B9^0)) -> -0.015695895 | J9: =B9 - (G9 - D9) / I9 -> 6391.5983 | K9: =C$35+J9 -> 45106.598 | L9: =J9-J10 -> 702.04492 | M9: =D9-G9 -> 5.7666978 | N9: =B9-J9 -> 367.40165 | O9: =(B9-B10)*(D10) -> 911881.35
A10: =A11+1 -> 26 | B10: =C10-C$35 -> 5847 | C10: 44562 | D10: 999.8699 | E10: 4.5 | F10: =IF(D10<D11,TRUE,FALSE) -> FALSE | G10: {=SUMPRODUCT(B10^{5,4,3,2,1,0}, LINEST(D$9:D$35,B$9:B$35^{1,2,3,4,5}))} -> 1017.2495 | H10: =IF(G10<G11,TRUE,FALSE) -> FALSE | I10: =(5*G$39*(B10^4))+(4*H$39*(B10^3))+(3*I$39*(B10^2))+(2*J$39*(B10^1))+(1*K$39*(B10^0)) -> 0.11038383 | J10: =B10 - (G10 - D10) / I10 -> 5689.5534 | K10: =C$35+J10 -> 44404.553 | L10: =J10-J11 -> 299.16412 | M10: =D10-G10 -> -17.379555 | N10: =B10-J10 -> 157.44658 | O10: =(B10-B11)*(D11) -> 349236.85
A11: =A12+1 -> 25 | B11: =C11-C$35 -> 5482 | C11: 44197 | D11: 956.8133 | E11: 4.5 | F11: =IF(D11<D12,TRUE,FALSE) -> FALSE | G11: {=SUMPRODUCT(B11^{5,4,3,2,1,0}, LINEST(D$9:D$35,B$9:B$35^{1,2,3,4,5}))} -> 970.18371 | H11: =IF(G11<G12,TRUE,FALSE) -> FALSE | I11: =(5*G$39*(B11^4))+(4*H$39*(B11^3))+(3*I$39*(B11^2))+(2*J$39*(B11^1))+(1*K$39*(B11^0)) -> 0.14594818 | J11: =B11 - (G11 - D11) / I11 -> 5390.3893 | K11: =C$35+J11 -> 44105.389 | L11: =J11-J12 -> 251.66805 | M11: =D11-G11 -> -13.370414 | N11: =B11-J11 -> 91.610694 | O11: =(B11-B12)*(D12) -> 335113.55
A12: =A13+1 -> 24 | B12: =C12-C$35 -> 5116 | C12: 43831 | D12: 915.6108 | E12: 6 | F12: =IF(D12<D13,TRUE,FALSE) -> FALSE | G12: {=SUMPRODUCT(B12^{5,4,3,2,1,0}, LINEST(D$9:D$35,B$9:B$35^{1,2,3,4,5}))} -> 911.70307 | H12: =IF(G12<G13,TRUE,FALSE) -> FALSE | I12: =(5*G$39*(B12^4))+(4*H$39*(B12^3))+(3*I$39*(B12^2))+(2*J$39*(B12^1))+(1*K$39*(B12^0)) -> 0.17198561 | J12: =B12 - (G12 - D12) / I12 -> 5138.7213 | K12: =C$35+J12 -> 43853.721 | L12: =J12-J13 -> 291.46902 | M12: =D12-G12 -> 3.9077286 | N12: =B12-J12 -> -22.721253 | O12: =(B12-B13)*(D13) -> 313553.52
A13: =A14+1 -> 23 | B13: =C13-C$35 -> 4753 | C13: 43468 | D13: 863.7838 | E13: 3.5 | F13: =IF(D13<D14,TRUE,FALSE) -> FALSE | G13: {=SUMPRODUCT(B13^{5,4,3,2,1,0}, LINEST(D$9:D$35,B$9:B$35^{1,2,3,4,5}))} -> 846.05281 | H13: =IF(G13<G14,TRUE,FALSE) -> FALSE | I13: =(5*G$39*(B13^4))+(4*H$39*(B13^3))+(3*I$39*(B13^2))+(2*J$39*(B13^1))+(1*K$39*(B13^0)) -> 0.18812273 | J13: =B13 - (G13 - D13) / I13 -> 4847.2522 | K13: =C$35+J13 -> 43562.252 | L13: =J13-J14 -> 155.73199 | M13: =D13-G13 -> 17.730988 | N13: =B13-J13 -> -94.252237 | O13: =(B13-B14)*(D14) -> 147719.56
A14: =A15+1 -> 22 | B14: =C14-C$35 -> 4576 | C14: 43291 | D14: 834.5738 | E14: 5 | F14: =IF(D14<D15,TRUE,FALSE) -> FALSE | G14: {=SUMPRODUCT(B14^{5,4,3,2,1,0}, LINEST(D$9:D$35,B$9:B$35^{1,2,3,4,5}))} -> 812.33099 | H14: =IF(G14<G15,TRUE,FALSE) -> FALSE | I14: =(5*G$39*(B14^4))+(4*H$39*(B14^3))+(3*I$39*(B14^2))+(2*J$39*(B14^1))+(1*K$39*(B14^0)) -> 0.19254469 | J14: =B14 - (G14 - D14) / I14 -> 4691.5202 | K14: =C$35+J14 -> 43406.52 | L14: =J14-J15 -> 206.40623 | M14: =D14-G14 -> 22.24281 | N14: =B14-J14 -> -115.52024 | O14: =(B14-B15)*(D15) -> 209040.84
A15: =A16+1 -> 21 | B15: =C15-C$35 -> 4313 | C15: 43028 | D15: 794.8321 | E15: 9 | F15: =IF(D15<D16,TRUE,FALSE) -> FALSE | G15: {=SUMPRODUCT(B15^{5,4,3,2,1,0}, LINEST(D$9:D$35,B$9:B$35^{1,2,3,4,5}))} -> 761.25274 | H15: =IF(G15<G16,TRUE,FALSE) -> FALSE | I15: =(5*G$39*(B15^4))+(4*H$39*(B15^3))+(3*I$39*(B15^2))+(2*J$39*(B15^1))+(1*K$39*(B15^0)) -> 0.1950995 | J15: =B15 - (G15 - D15) / I15 -> 4485.114 | K15: =C$35+J15 -> 43200.114 | L15: =J15-J16 -> 336.49784 | M15: =D15-G15 -> 33.579359 | N15: =B15-J15 -> -172.11402 | O15: =(B15-B16)*(D16) -> 73649.584
A16: =A17+1 -> 20 | B16: =C16-C$35 -> 4212 | C16: 42927 | D16: 729.2038 | E16: 1.8 | F16: =IF(D16<D17,TRUE,FALSE) -> FALSE | G16: {=SUMPRODUCT(B16^{5,4,3,2,1,0}, LINEST(D$9:D$35,B$9:B$35^{1,2,3,4,5}))} -> 741.55447 | H16: =IF(G16<G17,TRUE,FALSE) -> FALSE | I16: =(5*G$39*(B16^4))+(4*H$39*(B16^3))+(3*I$39*(B16^2))+(2*J$39*(B16^1))+(1*K$39*(B16^0)) -> 0.19485519 | J16: =B16 - (G16 - D16) / I16 -> 4148.6162 | K16: =C$35+J16 -> 42863.616 | L16: =J16-J17 -> 64.6014 | M16: =D16-G16 -> -12.350666 | N16: =B16-J16 -> 63.383816 | O16: =(B16-B17)*(D17) -> 129715.86
A17: =A18+1 -> 19 | B17: =C17-C$35 -> 4031 | C17: 42746 | D17: 716.6622 | E17: 8 | F17: =IF(D17<D18,TRUE,FALSE) -> FALSE | G17: {=SUMPRODUCT(B17^{5,4,3,2,1,0}, LINEST(D$9:D$35,B$9:B$35^{1,2,3,4,5}))} -> 706.44068 | H17: =IF(G17<G18,TRUE,FALSE) -> FALSE | I17: =(5*G$39*(B17^4))+(4*H$39*(B17^3))+(3*I$39*(B17^2))+(2*J$39*(B17^1))+(1*K$39*(B17^0)) -> 0.19280512 | J17: =B17 - (G17 - D17) / I17 -> 4084.0148 | K17: =C$35+J17 -> 42799.015 | L17: =J17-J18 -> 277.66143 | M17: =D17-G17 -> 10.221522 | N17: =B17-J17 -> -53.014785 | O17: =(B17-B18)*(D18) -> 95554.973
A18: =A19+1 -> 18 | B18: =C18-C$35 -> 3887 | C18: 42602 | D18: 663.5762 | E18: 3 | F18: =IF(D18<D19,TRUE,FALSE) -> FALSE | G18: {=SUMPRODUCT(B18^{5,4,3,2,1,0}, LINEST(D$9:D$35,B$9:B$35^{1,2,3,4,5}))} -> 678.88071 | H18: =IF(G18<G19,TRUE,FALSE) -> FALSE | I18: =(5*G$39*(B18^4))+(4*H$39*(B18^3))+(3*I$39*(B18^2))+(2*J$39*(B18^1))+(1*K$39*(B18^0)) -> 0.18977248 | J18: =B18 - (G18 - D18) / I18 -> 3806.3534 | K18: =C$35+J18 -> 42521.353 | L18: =J18-J19 -> 104.37564 | M18: =D18-G18 -> -15.304513 | N18: =B18-J18 -> 80.646642 | O18: =(B18-B19)*(D19) -> 105012.54
A19: =A20+1 -> 17 | B19: =C19-C$35 -> 3724 | C19: 42439 | D19: 644.2487 | E19: 6.8 | F19: =IF(D19<D20,TRUE,FALSE) -> FALSE | G19: {=SUMPRODUCT(B19^{5,4,3,2,1,0}, LINEST(D$9:D$35,B$9:B$35^{1,2,3,4,5}))} -> 648.32168 | H19: =IF(G19<G20,TRUE,FALSE) -> FALSE | I19: =(5*G$39*(B19^4))+(4*H$39*(B19^3))+(3*I$39*(B19^2))+(2*J$39*(B19^1))+(1*K$39*(B19^0)) -> 0.18494822 | J19: =B19 - (G19 - D19) / I19 -> 3701.9777 | K19: =C$35+J19 -> 42416.978 | L19: =J19-J20 -> 227.23909 | M19: =D19-G19 -> -4.0729826 | N19: =B19-J19 -> 22.022286 | O19: =(B19-B20)*(D20) -> 96516.656
A20: =A21+1 -> 16 | B20: =C20-C$35 -> 3564 | C20: 42279 | D20: 603.2291 | E20: 4 | F20: =IF(D20<D21,TRUE,FALSE) -> FALSE | G20: {=SUMPRODUCT(B20^{5,4,3,2,1,0}, LINEST(D$9:D$35,B$9:B$35^{1,2,3,4,5}))} -> 619.19762 | H20: =IF(G20<G21,TRUE,FALSE) -> FALSE | I20: =(5*G$39*(B20^4))+(4*H$39*(B20^3))+(3*I$39*(B20^2))+(2*J$39*(B20^1))+(1*K$39*(B20^0)) -> 0.17889624 | J20: =B20 - (G20 - D20) / I20 -> 3474.7386 | K20: =C$35+J20 -> 42189.739 | L20: =J20-J21 -> 133.88175 | M20: =D20-G20 -> -15.968524 | N20: =B20-J20 -> 89.261378 | O20: =(B20-B21)*(D21) -> 57422.762
... A34: =A35+1 -> 2 | B34: =C34-C$35 -> 370 | C34: 39085 | D34: 283.542 | E34: 9.9 | F34: =IF(D34<D35,TRUE,FALSE) -> FALSE | G34: {=SUMPRODUCT(B34^{5,4,3,2,1,0}, LINEST(D$9:D$35,B$9:B$35^{1,2,3,4,5}))} -> 293.04005 | H34: =IF(G34<G35,TRUE,FALSE) -> FALSE | I34: =(5*G$39*(B34^4))+(4*H$39*(B34^3))+(3*I$39*(B34^2))+(2*J$39*(B34^1))+(1*K$39*(B34^0)) -> 0.10161534 | J34: =B34 - (G34 - D34) / I34 -> 276.52937 | K34: =C$35+J34 -> 38991.529 | L34: =J34-J35 -> 200.27904 | M34: =D34-G34 -> -9.4980499 | N34: =B34-J34 -> 93.470628 | O34: =(B34-B35)*(D35) -> 95202
A35: 1 | B35: 1 | C35: 38715 | D35: 258 | E35: 0 | F35: =IF(D35<D36,TRUE,FALSE) -> FALSE | G35: {=SUMPRODUCT(B35^{5,4,3,2,1,0}, LINEST(D$9:D$35,B$9:B$35^{1,2,3,4,5}))} -> 246.19853 | H35: =IF(G35<G36,TRUE,FALSE) -> FALSE | I35: =(5*G$39*(B35^4))+(4*H$39*(B35^3))+(3*I$39*(B35^2))+(2*J$39*(B35^1))+(1*K$39*(B35^0)) -> 0.15682942 | J35: =B35 - (G35 - D35) / I35 -> 76.250329 | K35: =C$35+J35 -> 38791.25 | L35: 0 | M35: =D35-G35 -> 11.801466 | N35: =B35-J35 -> -75.250329
O36: =SUM(O9:O34) -> 4184554.9
B37: Test x | C37: Implied Date
B38: =C38-C$35 -> 6954 | C38: 45669 | D38: {=SUMPRODUCT(B38^{5,4,3,2,1,0}, LINEST(D$9:D$35,B$9:B$35^{1,2,3,4,5}))} -> 1057.8863 | G38: a | H38: b | I38: c | J38: d | K38: e | L38: f
B39: =C39-C$35 -> 6984 | C39: =C38+30 -> 45699 | D39: {=SUMPRODUCT(B39^{5,4,3,2,1,0}, LINEST(D$9:D$35,B$9:B$35^{1,2,3,4,5}))} -> 1056.3623 | F39: Coefficients | G39: {=LINEST(D9:D35, B9:B35^{1,2,3,4,5}, TRUE, TRUE)} -> 1.8600188e-16 | H39: -4.7839046e-12 | I39: 3.697167e-08 | J39: -9.4100796e-05 | K39: 0.15701751 | L39: 246.04161
B40: =C40-C$35 -> 7014 | C40: =C39+30 -> 45729 | D40: {=SUMPRODUCT(B40^{5,4,3,2,1,0}, LINEST(D$9:D$35,B$9:B$35^{1,2,3,4,5}))} -> 1054.6838 | G40: 1.7924818e-16 | H40: 3.0142686e-12 | I40: 1.8083973e-08 | J40: 4.6421498e-05 | K40: 0.047642479 | L40: 15.479116
B41: =C41-C$35 -> 7044 | C41: =C40+30 -> 45759 | D41: {=SUMPRODUCT(B41^{5,4,3,2,1,0}, LINEST(D$9:D$35,B$9:B$35^{1,2,3,4,5}))} -> 1052.8497 | F41: R^2 | G41: 0.99577023 | H41: 16.804414 | I41: #N/A | J41: #N/A | K41: #N/A | L41: #N/A
B42: =C42-C$35 -> 7074 | C42: =C41+30 -> 45789 | D42: {=SUMPRODUCT(B42^{5,4,3,2,1,0}, LINEST(D$9:D$35,B$9:B$35^{1,2,3,4,5}))} -> 1050.8591 | G42: 988.76208 | H42: 21 | I42: #N/A | J42: #N/A | K42: #N/A | L42: #N/A
B43: =C43-C$35 -> 7104 | C43: =C42+30 -> 45819 | D43: {=SUMPRODUCT(B43^{5,4,3,2,1,0}, LINEST(D$9:D$35,B$9:B$35^{1,2,3,4,5}))} -> 1048.7112 | G43: 1396074.3 | H43: 5930.1548 | I43: #N/A | J43: #N/A | K43: #N/A | L43: #N/A
B44: =C44-C$35 -> 7134 | C44: =C43+30 -> 45849 | D44: {=SUMPRODUCT(B44^{5,4,3,2,1,0}, LINEST(D$9:D$35,B$9:B$35^{1,2,3,4,5}))} -> 1046.4051
B45: =C45-C$35 -> 7164 | C45: =C44+30 -> 45879 | D45: {=SUMPRODUCT(B45^{5,4,3,2,1,0}, LINEST(D$9:D$35,B$9:B$35^{1,2,3,4,5}))} -> 1043.94
B46: =C46-C$35 -> 7194 | C46: =C45+30 -> 45909 | D46: {=SUMPRODUCT(B46^{5,4,3,2,1,0}, LINEST(D$9:D$35,B$9:B$35^{1,2,3,4,5}))} -> 1041.3151 | F46: Goal Seek: When the Price is scheduled to start declining
B47: =C47-C$35 -> 7224 | C47: =C46+30 -> 45939 | D47: {=SUMPRODUCT(B47^{5,4,3,2,1,0}, LINEST(D$9:D$35,B$9:B$35^{1,2,3,4,5}))} -> 1038.5297 | F47: Day Number | G47: Slope Breaks Even | H47: Date | I47: Price
B48: =C48-C$35 -> 7254 | C48: =C47+30 -> 45969 | D48: {=SUMPRODUCT(B48^{5,4,3,2,1,0}, LINEST(D$9:D$35,B$9:B$35^{1,2,3,4,5}))} -> 1035.5831 | F48: 6660 | G48: =(5*G$39*(F48^4))+(4*H$39*(F48^3))+(3*I$39*(F48^2))+(2*J$39*(F48^1))+(1*K$39*(F48^0)) -> 0.00019458894 | H48: =C35+F48 -> 45375 | I48: {=SUMPRODUCT(F48^{5,4,3,2,1,0}, LINEST(D$9:D$35,B$9:B$35^{1,2,3,4,5}))} -> 1064.8577
B49: =C49-C$35 -> 7284 | C49: =C48+30 -> 45999 | D49: {=SUMPRODUCT(B49^{5,4,3,2,1,0}, LINEST(D$9:D$35,B$9:B$35^{1,2,3,4,5}))} -> 1032.4747
B50: =C50-C$35 -> 7314 | C50: =C49+30 -> 46029 | D50: {=SUMPRODUCT(B50^{5,4,3,2,1,0}, LINEST(D$9:D$35,B$9:B$35^{1,2,3,4,5}))} -> 1029.2037
B51: =C51-C$35 -> 7344 | C51: =C50+30 -> 46059 | D51: {=SUMPRODUCT(B51^{5,4,3,2,1,0}, LINEST(D$9:D$35,B$9:B$35^{1,2,3,4,5}))} -> 1025.7697
B52: =C52-C$35 -> 7374 | C52: =C51+30 -> 46089 | D52: {=SUMPRODUCT(B52^{5,4,3,2,1,0}, LINEST(D$9:D$35,B$9:B$35^{1,2,3,4,5}))} -> 1022.1721
B53: =C53-C$35 -> 7404 | C53: =C52+30 -> 46119 | D53: {=SUMPRODUCT(B53^{5,4,3,2,1,0}, LINEST(D$9:D$35,B$9:B$35^{1,2,3,4,5}))} -> 1018.4104
B54: =C54-C$35 -> 7434 | C54: =C53+30 -> 46149 | D54: {=SUMPRODUCT(B54^{5,4,3,2,1,0}, LINEST(D$9:D$35,B$9:B$35^{1,2,3,4,5}))} -> 1014.4841
B55: =C55-C$35 -> 7464 | C55: =C54+30 -> 46179 | D55: {=SUMPRODUCT(B55^{5,4,3,2,1,0}, LINEST(D$9:D$35,B$9:B$35^{1,2,3,4,5}))} -> 1010.3927
...

Sheet STOCK
A1: Date | B1: Real Price | I1: https://www.digrin.com/stocks/detail/CELG/price
A2: October 2019 | B2: 108.03 | C2: =100*(B2-B3)/B3 -> 8.7915408 | D2: 43739
A3: September 2019 | B3: 99.3 | C3: =100*(B3-B4)/B4 -> 2.5826446 | D3: =EDATE(D2,-1) -> 43709
A4: August 2019 | B4: 96.8 | C4: =100*(B4-B5)/B5 -> 5.3777487 | D4: =EDATE(D3,-1) -> 43678
A5: July 2019 | B5: 91.86 | C5: =100*(B5-B6)/B6 -> -0.62743401 | D5: =EDATE(D4,-1) -> 43647
A6: June 2019 | B6: 92.44 | C6: =100*(B6-B7)/B7 -> -1.4393859 | D6: =EDATE(D5,-1) -> 43617
A7: May 2019 | B7: 93.79 | C7: =100*(B7-B8)/B8 -> -0.91907881 | D7: =EDATE(D6,-1) -> 43586
A8: April 2019 | B8: 94.66 | C8: =100*(B8-B9)/B9 -> 0.33919864 | D8: =EDATE(D7,-1) -> 43556
A9: March 2019 | B9: 94.34 | C9: =100*(B9-B10)/B10 -> 13.498556 | D9: =EDATE(D8,-1) -> 43525
A10: February 2019 | B10: 83.12 | C10: =100*(B10-B11)/B11 -> -6.0366267 | D10: =EDATE(D9,-1) -> 43497
A11: January 2019 | B11: 88.46 | C11: =100*(B11-B12)/B12 -> 38.024653 | D11: =EDATE(D10,-1) -> 43466
A12: December 2018 | B12: 64.09 | C12: =100*(B12-B13)/B13 -> -11.257269 | D12: =EDATE(D11,-1) -> 43435
A13: November 2018 | B13: 72.22 | C13: =100*(B13-B14)/B14 -> 0.86592179 | D13: =EDATE(D12,-1) -> 43405
A14: October 2018 | B14: 71.6 | C14: =100*(B14-B15)/B15 -> -19.99106 | D14: =EDATE(D13,-1) -> 43374
... A389: July 1987 | B389: 0.51 | C389: =100*(B389-B390)/B390 -> #DIV/0! | D389: =EDATE(D388,-1) -> 31959

Sheet MEDICARE D
A1: Year | B1: Brand Name | C1: Generic Name | D1: Total Spending | E1: Beneficiary Count | F1: Unit Count | G1: Beneficiary Cost Share | H1: Total Annual Spending Per User | I1: Avg Cost Per Unit | J1: Average Annual Beneficiary Cost Share | K1: Claim Count | L1: Beneficiary Count LIS | M1: Beneficiary Count No LIS | N1: Beneficiary Cost Share LIS | O1: Beneficiary Cost Share No LIS | P1: Avg Bene Cost Share LIS | Q1: Avg Bene Cost Share No LIS | R1: Calc_Average_Spending_Per_Claim | S1: Source | T1: Column1
A2: 2023 | B2: Revlimid | C2: Lenalidomide | D2: 3.8598048e+09 | E2: 36967 | F2: 4395154 | G2: * | H2: 104412.17 | I2: 878.2122 | J2: * | K2: 216207 | L2: * | M2: * | N2: * | O2: * | P2: * | Q2: * | R2: 17852.358 | S2: 46Brooklyn | T2: *
A3: 2022 | B3: Revlimid | C3: Lenalidomide | D3: 5.9350511e+09 | E3: 45557 | F3: 6720907 | G3: * | H3: 130277.48 | I3: 883.09618 | J3: * | K3: 329329 | L3: * | M3: * | N3: * | O3: * | P3: * | Q3: * | R3: 18021.647 | S3: 46Brooklyn | T3: *
A4: 2021 | B4: Revlimid | C4: Lenalidomide | D4: 5893547689 | E4: 45601 | F4: 7014892 | G4: * | H4: 129241.63 | I4: 840.17444 | J4: * | K4: 344297 | L4: * | M4: * | N4: * | O4: * | P4: * | Q4: * | R4: 17117.627 | S4: 46Brooklyn | T4: *
A5: 2020 | B5: Revlimid | C5: Lenalidomide | D5: 5356050275 | E5: 43747 | F5: 6742991 | G5: * | H5: 122432.4 | I5: 794.32803 | J5: * | K5: 329864 | L5: * | M5: * | N5: * | O5: * | P5: * | Q5: * | R5: 16237.147 | S5: 46Brooklyn | T5: *
A6: 2019 | B6: Revlimid | C6: Lenalidomide | D6: 4673095052 | E6: 42209 | F6: 6267746 | G6: * | H6: 110713.24 | I6: 745.5885 | J6: * | K6: 307890 | L6: * | M6: * | N6: * | O6: * | P6: * | Q6: * | R6: 15177.807 | S6: 46Brooklyn | T6: *
A7: 2018 | B7: Revlimid | C7: Lenalidomide | D7: 4064871916 | E7: 39454 | F7: 5828985 | G7: * | H7: 103028.13 | I7: 697.35425 | J7: * | K7: 285915 | L7: * | M7: * | N7: * | O7: * | P7: * | Q7: * | R7: 14217.064 | S7: 46Brooklyn | T7: *
A8: 2017 | B8: Revlimid | C8: Lenalidomide | D8: 3311187483 | E8: 37415 | F8: 5281271 | G8: * | H8: 88498.93 | I8: 626.92601 | J8: * | K8: 259573 | L8: * | M8: * | N8: * | O8: * | P8: * | Q8: * | R8: 12756.286 | S8: 46Brooklyn | T8: *
A9: 2016 | B9: Revlimid | C9: Lenalidomide | D9: 2661152949 | E9: 35369 | F9: 4895379 | G9: * | H9: 75239.7 | I9: 543.59117 | J9: * | K9: 239052 | L9: * | M9: * | N9: * | O9: * | P9: * | Q9: * | R9: 11132.109 | S9: 46Brooklyn | T9: *
A10: 2015 | B10: Revlimid | C10: Lenalidomide | D10: 2077425469 | E10: 30453 | F10: 4240330 | G10: * | H10: 68217.432 | I10: 489.92071 | J10: * | K10: 204834 | L10: * | M10: * | N10: * | O10: * | P10: * | Q10: * | R10: 10141.995 | S10: 46Brooklyn | T10: *
A11: 2014 | B11: Revlimid | C11: Lenalidomide | D11: 1.6716227e+09 | E11: 27143 | F11: 3707616 | G11: 82121407 | H11: 61585.774 | I11: 450.86186 | J11: * | K11: 178377 | L11: 6319 | M11: 20824 | N11: 984710.56 | O11: 81136697 | P11: 155.83329 | Q11: 3896.307 | S11: Wayback
A12: 2013 | B12: Revlimid | C12: Lenalidomide | D12: 1.3499646e+09 | E12: 24637 | F12: 3227606 | G12: 70445321 | H12: 54794.195 | I12: 418.2557 | J12: * | K12: 153782 | L12: 6019 | M12: 18618 | N12: 869863.72 | O12: 69575457 | P12: 144.51964 | Q12: 3736.9995 | S12: Wayback | T12: *
A13: 2012 | B13: Revlimid | C13: Lenalidomide | D13: 1.0171953e+09 | E13: 20391 | F13: 2612956.2 | G13: 59667105 | H13: 49884.525 | I13: 389.28908 | J13: * | K13: 124546 | L13: 5572 | M13: 14819 | N13: 826135.25 | O13: 58840969 | P13: 148.26548 | Q13: 3970.6437 | S13: Wayback | T13: *
A14: 2011 | B14: Revlimid | C14: Lenalidomide | D14: 8.0910253e+08 | E14: 17844 | F14: 2205662 | G14: 49069914 | H14: 45343.114 | I14: 366.82979 | J14: * | K14: 104141 | L14: 5008 | M14: 12836 | N14: 772615.54 | O14: 48297299 | P14: 154.27627 | Q14: 3762.644 | S14: Wayback
A15: 2010 | B15: Revlimid | C15: Lenalidomide | D15: 5.9655644e+08 | E15: 14670 | F15: 1703090 | G15: 53532052 | H15: 40665.061 | I15: 350.27887 | J15: * | K15: 80350 | L15: 4204 | M15: 10466 | N15: 908060.97 | O15: 52623991 | P15: 215.99928 | Q15: 5028.0901 | S15: Wayback

Sheet Medicare Cost
A1: brand_name | B1: generic_name | C1: manufacturer | D1: 2019_total_spending | E1: 2019_total_dosage_units | F1: 2019_total_claims | G1: 2019_total_beneficiaries | H1: 2019_average_spending_per_dosage_unit_weighted | I1: 2019_average_spending_per_claim | J1: 2019_average_spending_per_beneficiary | K1: 2019_outlier_flag | L1: 2020_total_spending | M1: 2020_total_dosage_units | N1: 2020_total_claims | O1: 2020_total_beneficiaries | P1: 2020_average_spending_per_dosage_unit_weighted | Q1: 2020_average_spending_per_claim | R1: 2020_average_spending_per_beneficiary | S1: 2020_outlier_flag | T1: 2021_total_spending | U1: 2021_total_dosage_units | V1: 2021_total_claims | W1: 2021_total_beneficiaries | X1: 2021_average_spending_per_dosage_unit_weighted | Y1: 2021_average_spending_per_claim | Z1: 2021_average_spending_per_beneficiary | AA1: 2021_outlier_flag | AB1: 2022_total_spending | AC1: 2022_total_dosage_units | AD1: 2022_total_claims | AE1: 2022_total_beneficiaries | AF1: 2022_average_spending_per_dosage_unit_weighted | AG1: 2022_average_spending_per_claim | AH1: 2022_average_spending_per_beneficiary | AI1: 2022_outlier_flag | AJ1: 2023_total_spending | AK1: 2023_total_dosage_units | AL1: 2023_total_claims | AM1: 2023_total_beneficiaries | AN1: 2023_average_spending_per_dosage_unit_weighted | AO1: 2023_average_spending_per_claim | AP1: 2023_average_spending_per_beneficiary | AQ1: 2023_outlier_flag | AR1: yearly_change_change_in_average_spending_per_dosage_unit_2022_2023 | AS1: annual_growth_rate_in_average_spending_per_dosage_unit_2019_2023
A2: Revlimid | B2: Lenalidomide | C2: Celgene/BMS | D2: 4673095052 | E2: 6267746 | F2: 307890 | G2: 42209 | H2: 745.5885 | I2: 15177.807 | J2: 110713.24 | K2: 0 | L2: 5356050275 | M2: 6742991 | N2: 329864 | O2: 43747 | P2: 794.32803 | Q2: 16237.147 | R2: 122432.4 | S2: 0 | T2: 5893547689 | U2: 7014892 | V2: 344297 | W2: 45601 | X2: 840.17444 | Y2: 17117.627 | Z2: 129241.63 | AA2: 0 | AB2: 5935051092 | AC2: 6720907 | AD2: 329329 | AE2: 45557 | AF2: 883.09618 | AG2: 18021.647 | AH2: 130277.48 | AI2: 0 | AJ2: 3859804789 | AK2: 4395154 | AL2: 216207 | AM2: 36967 | AN2: 878.2122 | AO2: 17852.358 | AP2: 104412.17 | AQ2: 0 | AR2: -0.00553052 | AS2: 0.041777723
A3: Brnd_Name | B3: Gnrc_Name | C3: Tot_Mftr | D3: Mftr_Name | E3: Tot_Spndng_2017 | F3: Tot_Dsg_Unts_2017 | G3: Tot_Clms_2017 | H3: Tot_Benes_2017 | I3: Avg_Spnd_Per_Dsg_Unt_Wghtd_2017 | J3: Avg_Spnd_Per_Clm_2017 | K3: Avg_Spnd_Per_Bene_2017 | L3: Outlier_Flag_2017 | M3: Tot_Spndng_2018 | N3: Tot_Dsg_Unts_2018 | O3: Tot_Clms_2018 | P3: Tot_Benes_2018 | Q3: Avg_Spnd_Per_Dsg_Unt_Wghtd_2018 | R3: Avg_Spnd_Per_Clm_2018 | S3: Avg_Spnd_Per_Bene_2018 | T3: Outlier_Flag_2018 | U3: Tot_Spndng_2019 | V3: Tot_Dsg_Unts_2019 | W3: Tot_Clms_2019 | X3: Tot_Benes_2019 | Y3: Avg_Spnd_Per_Dsg_Unt_Wghtd_2019 | Z3: Avg_Spnd_Per_Clm_2019 | AA3: Avg_Spnd_Per_Bene_2019 | AB3: Outlier_Flag_2019 | AC3: Tot_Spndng_2020 | AD3: Tot_Dsg_Unts_2020 | AE3: Tot_Clms_2020 | AF3: Tot_Benes_2020 | AG3: Avg_Spnd_Per_Dsg_Unt_Wghtd_2020 | AH3: Avg_Spnd_Per_Clm_2020 | AI3: Avg_Spnd_Per_Bene_2020 | AJ3: Outlier_Flag_2020 | AK3: Tot_Spndng_2021 | AL3: Tot_Dsg_Unts_2021 | AM3: Tot_Clms_2021 | AN3: Tot_Benes_2021 | AO3: Avg_Spnd_Per_Dsg_Unt_Wghtd_2021 | AP3: Avg_Spnd_Per_Clm_2021 | AQ3: Avg_Spnd_Per_Bene_2021 | AR3: Outlier_Flag_2021 | AS3: Chg_Avg_Spnd_Per_Dsg_Unt_20_21 | AT3: CAGR_Avg_Spnd_Per_Dsg_Unt_17_21
A4: Revlimid | B4: Lenalidomide | C4: 1 | D4: Overall | E4: 3311187483 | F4: 5281271 | G4: 259573 | H4: 37415 | I4: 626.92601 | J4: 12756.286 | K4: 88498.93 | L4: 0 | M4: 4064871916 | N4: 5828985 | O4: 285915 | P4: 39454 | Q4: 697.35425 | R4: 14217.064 | S4: 103028.13 | T4: 0 | U4: 4673095052 | V4: 6267746 | W4: 307890 | X4: 42209 | Y4: 745.5885 | Z4: 15177.807 | AA4: 110713.24 | AB4: 0 | AC4: 5356050275 | AD4: 6742991 | AE4: 329864 | AF4: 43747 | AG4: 794.32803 | AH4: 16237.147 | AI4: 122432.4 | AJ4: 0 | AK4: 5893547689 | AL4: 7014892 | AM4: 344297 | AN4: 45601 | AO4: 840.17444 | AP4: 17117.627 | AQ4: 129241.63 | AR4: 0 | AS4: 0.057717236 | AT4: 0.075940596
A5: Revlimid | B5: Lenalidomide | C5: 1 | D5: Celgene/BMS | E5: 3311187483 | F5: 5281271 | G5: 259573 | H5: 37415 | I5: 626.92601 | J5: 12756.286 | K5: 88498.93 | L5: 0 | M5: 4064871916 | N5: 5828985 | O5: 285915 | P5: 39454 | Q5: 697.35425 | R5: 14217.064 | S5: 103028.13 | T5: 0 | U5: 4673095052 | V5: 6267746 | W5: 307890 | X5: 42209 | Y5: 745.5885 | Z5: 15177.807 | AA5: 110713.24 | AB5: 0 | AC5: 5356050275 | AD5: 6742991 | AE5: 329864 | AF5: 43747 | AG5: 794.32803 | AH5: 16237.147 | AI5: 122432.4 | AJ5: 0 | AK5: 5893547689 | AL5: 7014892 | AM5: 344297 | AN5: 45601 | AO5: 840.17444 | AP5: 17117.627 | AQ5: 129241.63 | AR5: 0 | AS5: 0.057717236 | AT5: 0.075940596
D8: Calendar Year 2013 | K8: Calendar Year 2014 | R8: Calendar Year 2015 | Y8: Calendar Year 2016 | AF8: Calendar Year 2017 | AM8: Yearly Change
A9: Brand Name | B9: Generic Name | C9: Number of Manufacturers | D9: Total Spending | E9: Total Dosage Units | F9: Total Claims | G9: Total Beneficiaries | H9: Average Spending Per Dosage Unit (Weighted) | I9: Average Spending Per Claim | J9: Average Spending Per Beneficiary | K9: Total Spending | L9: Total Dosage Units | M9: Total Claims | N9: Total Beneficiaries | O9: Average Spending Per Dosage Unit (Weighted) | P9: Average Spending Per Claim | Q9: Average Spending Per Beneficiary | R9: Total Spending | S9: Total Dosage Units | T9: Total Claims | U9: Total Beneficiaries | V9: Average Spending Per Dosage Unit (Weighted) | W9: Average Spending Per Claim | X9: Average Spending Per Beneficiary | Y9: Total Spending | Z9: Total Dosage Units | AA9: Total Claims | AB9: Total Beneficiaries | AC9: Average Spending Per Dosage Unit (Weighted) | AD9: Average Spending Per Claim | AE9: Average Spending Per Beneficiary | AF9: Total Spending | AG9: Total Dosage Units | AH9: Total Claims | AI9: Total Beneficiaries | AJ9: Average Spending Per Dosage Unit (Weighted) | AK9: Average Spending Per Claim | AL9: Average Spending Per Beneficiary | AM9: Change in Average Spending Per Dosage Unit (2016-2017) | AN9: Annual Growth Rate in Average Spending Per Dosage Unit (2013-2017)
A10: Revlimid | B10: Lenalidomide | C10: 1 | D10: 1.3499646e+09 | E10: 3227606 | F10: 153782 | G10: 24636 | H10: 418.39983 | I10: 8778.4305 | J10: 54796.42 | K10: 1.6716227e+09 | L10: 3707616 | M10: 178377 | N10: 27143 | O10: 450.96504 | P10: 9371.2903 | Q10: 61585.774 | R10: 2.0774255e+09 | S10: 4240330 | T10: 204870 | U10: 30453 | V10: 489.91125 | W10: 10140.213 | X10: 68217.432 | Y10: 2661602600 | Z10: 4896215 | AA10: 239093 | AB10: 35376 | AC10: 543.5902 | AD10: 11132.081 | AE10: 75237.523 | AF10: 3.3127733e+09 | AG10: 5283681 | AH10: 259693 | AI10: 37459 | AJ10: 626.94005 | AK10: 12756.498 | AL10: 88437.312 | AM10: 0.15333214 | AN10: 0.10639098
A14: Year | B14: Brand Name | C14: Generic Name | D14: Coverage Type | E14: Total Spending | F14: Beneficiary Count | G14: Unit Count | H14: Beneficiary Cost Share | I14: Total Annual Spending Per User | J14: Avg Cost Per Unit | K14: Average Annual Beneficiary Cost Share | L14: Claim Count | M14: Beneficiary Count LIS | N14: Beneficiary Count No LIS | O14: Beneficiary Cost Share LIS | P14: Beneficiary Cost Share No LIS | Q14: Avg Bene Cost Share LIS | R14: Avg Bene Cost Share No LIS
A15: 2010 | B15: Revlimid | C15: Lenalidomide | D15: Part D | E15: 5.9655644e+08 | F15: 14670 | G15: 1703090 | H15: 53532052 | I15: 40665.061 | J15: 350.27887 | K15: * | L15: 80350 | M15: 4204 | N15: 10466 | O15: 908060.97 | P15: 52623991 | Q15: 215.99928 | R15: 5028.0901
A16: 2011 | B16: Revlimid | C16: Lenalidomide | D16: Part D | E16: 8.0910253e+08 | F16: 17844 | G16: 2205662 | H16: 49069914 | I16: 45343.114 | J16: 366.82979 | K16: * | L16: 104141 | M16: 5008 | N16: 12836 | O16: 772615.54 | P16: 48297299 | Q16: 154.27627 | R16: 3762.644
A17: 2012 | B17: Revlimid | C17: Lenalidomide | D17: Part D | E17: 1.0171953e+09 | F17: 20391 | G17: 2612956.2 | H17: 59667105 | I17: 49884.525 | J17: 389.28908 | K17: * | L17: 124546 | M17: 5572 | N17: 14819 | O17: 826135.25 | P17: 58840969 | Q17: 148.26548 | R17: 3970.6437
A18: 2013 | B18: Revlimid | C18: Lenalidomide | D18: Part D | E18: 1.3499646e+09 | F18: 24637 | G18: 3227606 | H18: 70445321 | I18: 54794.195 | J18: 418.2557 | K18: * | L18: 153782 | M18: 6019 | N18: 18618 | O18: 869863.72 | P18: 69575457 | Q18: 144.51964 | R18: 3736.9995
A19: 2014 | B19: Revlimid | C19: Lenalidomide | D19: Part D | E19: 1.6716227e+09 | F19: 27143 | G19: 3707616 | H19: 82121407 | I19: 61585.774 | J19: 450.86186 | K19: * | L19: 178377 | M19: 6319 | N19: 20824 | O19: 984710.56 | P19: 81136697 | Q19: 155.83329 | R19: 3896.307
A21: REVLIMID-MEDICARE DATA SEE SHEET TITLED REVLIMID_REDBOOK
A22: Year | B22: Medicare Avg Cost/Unit
A23: =A15 -> 2010 | B23: =J15 -> 350.27887
A24: =A16 -> 2011 | B24: =J16 -> 366.82979
A25: =A17 -> 2012 | B25: =J17 -> 389.28908
A26: =A18 -> 2013 | B26: =H10 -> 418.39983
A27: =A19 -> 2014 | B27: =O10 -> 450.96504
A28: 2015 | B28: =V10 -> 489.91125
A29: =A28+1 -> 2016 | B29: =AC10 -> 543.5902
A30: =A29+1 -> 2017 | B30: =AJ10 -> 626.94005
A31: =A30+1 -> 2018 | B31: =Q4 -> 697.35425
A32: =A31+1 -> 2019 | B32: =Y4 -> 745.5885
A33: =A32+1 -> 2020 | B33: =P2 -> 794.32803
A34: =A33+1 -> 2021 | B34: =X2 -> 840.17444
A35: =A34+1 -> 2022 | B35: =AF2 -> 883.09618
A36: =A35+1 -> 2023 | B36: =AN2 -> 878.2122

Sheet Sheet1
A1: REVLIMID-MEDICARE DATA SEE SHEET TITLED REVLIMID_REDBOOK
A2: Year | B2: Medicare Avg Cost/Unit
A3: 2010 | B3: 350.27887
A4: 2011 | B4: 366.82979
A5: 2012 | B5: 389.28908
A6: 2013 | B6: 418.39983
A7: 2014 | B7: 450.96504
A8: 2015 | B8: 489.91125
A9: 2016 | B9: 543.5902
A10: 2017 | B10: 626.94005
A11: 2018 | B11: 697.35425
A12: 2019 | B12: 745.5885
A13: 2020 | B13: 794.32803
A14: 2021 | B14: 840.17444
... A16: 2023 | B16: 878.2122

Sheet Datawrapper Graph
A1: Effective Date | B1: Unit | C1: Year | D1: Avg Cost/Unit
A2: 38715 | B2: 258 | C2: 40543 | D2: ='Medicare Cost'!B23 -> 350.27887
A3: 39085 | B3: 283.542 | C3: =C2+365 -> 40908 | D3: ='Medicare Cost'!B24 -> 366.82979
A4: 39451 | B4: 311.6127 | C4: 41274 | D4: ='Medicare Cost'!B25 -> 389.28908
A5: 39787 | B5: 324.0771 | C5: =C4+365 -> 41639 | D5: ='Medicare Cost'!B26 -> 418.39983
A6: 39939 | B6: 356.2904 | C6: =C5+365 -> 42004 | D6: ='Medicare Cost'!B27 -> 450.96504
A7: 40183 | B7: 388.0003 | C7: =C6+365 -> 42369 | D7: ='Medicare Cost'!B28 -> 489.91125
A8: 40523 | B8: 415.1557 | C8: 42735 | D8: ='Medicare Cost'!B29 -> 543.5902
A9: 40876 | B9: 440.0651 | C9: =C8+365 -> 43100 | D9: ='Medicare Cost'!B30 -> 626.94005
A10: 41214 | B10: 466.4691 | C10: =C9+365 -> 43465 | D10: ='Medicare Cost'!B31 -> 697.35425
A11: 41363 | B11: 480.4631 | C11: =C10+365 -> 43830 | D11: ='Medicare Cost'!B32 -> 745.5885
A12: 41548 | B12: 494.877 | C12: =C11+366 -> 44196 | D12: ='Medicare Cost'!B33 -> 794.32803
A13: 41704 | B13: 514.6721 | C13: =C12+365 -> 44561 | D13: ='Medicare Cost'!B34 -> 840.17444
A14: 41885 | B14: 546.732 | C14: =C13+365 -> 44926 | D14: ='Medicare Cost'!B35 -> 883.09618
A15: 41996 | B15: 563.1339 | C15: =C14+365 -> 45291 | D15: ='Medicare Cost'!B36 -> 878.2122
A16: 42180 | B16: 580.0279
A17: 42279 | B17: 603.2291
A18: 42439 | B18: 644.2487
A19: 42602 | B19: 663.5762
A20: 42746 | B20: 716.6622
A21: 42927 | B21: 729.2038
A22: 43028 | B22: 794.8321
A23: 43291 | B23: 834.5738
A24: 43468 | B24: 863.7838
A25: 43831 | B25: 915.6108
A26: 44197 | B26: 956.8133
A27: 44562 | B27: 999.8699
A28: 45474 | B28: 1069.8608
