Workbook

Sheet Manufacturer Info
A1: Manufacturer/Distributor | B1: Address 1 | C1: Address 2 | D1: City | E1: State | F1: Zip | G1: Phone | H1: Company Web Site | I1: Company E-Mail Address | J1: Toll Free | K1: Clinical Support | L1: Parent Company
A2: BRISTOL-MYERS SQUIBB CO. | B2: P. O. BOX 4500 | D2: PRINCETON | E2: NJ | F2: 08543 | G2: (609) 897-2000

Sheet REDBOOKSearchResults
A1: Manufacturer/Distributor | B1: Product Name | C1: Application | D1: Deactivated Status | E1: Deactivated Date | F1: Active Ingredient | G1: Generic | H1: Repackager | I1: Orange Book Code | J1: Code Type | K1: Identifier | L1: Form | M1: Strength | N1: Route | O1: Package Size | P1: Unit Dose | Q1: WAC Package Price | R1: WAC Effective Date | S1: New WAC | T1: New WAC Effective Date | U1: AWP Package Price | V1: AWP Unit Price | W1: AWP Effective Date | X1: New AWP | Y1: New AWP Effective Date | Z1: DIRP Package Price | AA1: DIRP Effective Date | AB1: New DIRP | AC1: New DIRP Effective Date | AD1: SRP Package Price | AE1: SRP Effective Date | AF1: New SRP | AG1: New SRP Effective Date | AH1: Dea Class | AI1: Significant Omission | AJ1: Add'l Description
A2: BRISTOL-MYERS SQUIBB CO. | B2: POMALYST | C2: NDA | D2: N | F2: pomalidomide | G2: N | H2: N | J2: NDC | K2: 59572-0504-21 | L2: CAP | M2: 4 mg | N2: ORAL | O2: 21s ea | P2: N | Q2: 25049.70 | R2: 01/01/2026 | U2: 30059.64 | V2: 1431.41143 | W2: 01/01/2026 | AH2: RX
A3: BRISTOL-MYERS SQUIBB CO. | B3: POMALYST | C3: NDA | D3: N | F3: pomalidomide | G3: N | H3: N | J3: NDC | K3: 59572-0504-00 | L3: CAP | M3: 4 mg | N3: ORAL | O3: 100s ea | P3: N | Q3: 119284.25 | R3: 01/01/2026 | U3: 143141.10 | V3: 1431.41100 | W3: 01/01/2026 | AH3: RX
A4: BRISTOL-MYERS SQUIBB CO. | B4: POMALYST | C4: NDA | D4: N | F4: pomalidomide | G4: N | H4: N | J4: NDC | K4: 59572-0503-21 | L4: CAP | M4: 3 mg | N4: ORAL | O4: 21s ea | P4: N | Q4: 25049.70 | R4: 01/01/2026 | U4: 30059.64 | V4: 1431.41143 | W4: 01/01/2026 | AH4: RX
A5: BRISTOL-MYERS SQUIBB CO. | B5: POMALYST | C5: NDA | D5: N | F5: pomalidomide | G5: N | H5: N | J5: NDC | K5: 59572-0503-00 | L5: CAP | M5: 3 mg | N5: ORAL | O5: 100s ea | P5: N | Q5: 119284.25 | R5: 01/01/2026 | U5: 143141.10 | V5: 1431.41100 | W5: 01/01/2026 | AH5: RX
A6: BRISTOL-MYERS SQUIBB CO. | B6: POMALYST | C6: NDA | D6: N | F6: pomalidomide | G6: N | H6: N | J6: NDC | K6: 59572-0502-21 | L6: CAP | M6: 2 mg | N6: ORAL | O6: 21s ea | P6: N | Q6: 25049.70 | R6: 01/01/2026 | U6: 30059.64 | V6: 1431.41143 | W6: 01/01/2026 | AH6: RX
A7: BRISTOL-MYERS SQUIBB CO. | B7: POMALYST | C7: NDA | D7: N | F7: pomalidomide | G7: N | H7: N | J7: NDC | K7: 59572-0502-00 | L7: CAP | M7: 2 mg | N7: ORAL | O7: 100s ea | P7: N | Q7: 119284.25 | R7: 01/01/2026 | U7: 143141.10 | V7: 1431.41100 | W7: 01/01/2026 | AH7: RX
A8: BRISTOL-MYERS SQUIBB CO. | B8: POMALYST | C8: NDA | D8: N | F8: pomalidomide | G8: N | H8: N | J8: NDC | K8: 59572-0501-00 | L8: CAP | M8: 1 mg | N8: ORAL | O8: 100s ea | P8: N | Q8: 119284.25 | R8: 01/01/2026 | U8: 143141.10 | V8: 1431.41100 | W8: 01/01/2026 | AH8: RX
A9: BRISTOL-MYERS SQUIBB CO. | B9: POMALYST | C9: NDA | D9: N | F9: pomalidomide | G9: N | H9: N | J9: NDC | K9: 59572-0501-21 | L9: CAP | M9: 1 mg | N9: ORAL | O9: 21s ea | P9: N | Q9: 25049.70 | R9: 01/01/2026 | U9: 30059.64 | V9: 1431.41143 | W9: 01/01/2026 | AH9: RX

Sheet Sheet1
A1: =REDBOOKSearchResults!B1 -> Product Name | B1: Effective Date | C1: Unit | D1: % Change | E1: Identifier | F1: Strength | G1: Package Size
A2: =REDBOOKSearchResults!B$2 -> POMALYST | B2: 46023 | C2: 1431.4114 | D2: 4.5 | E2: 59572-0504-21 | F2: =INDEX(REDBOOKSearchResults!$A$1:$AK$100, MATCH($E2, INDEX(REDBOOKSearchResults!$A$1:$AK$100, 0, MATCH($E$1, REDBOOKSearchResults!$1:$1, 0)), 0), MATCH(F$1, REDBOOKSearchResults!$1:$1, 0)) -> 4 mg | G2: =INDEX(REDBOOKSearchResults!$A$1:$AK$100, MATCH($E2, INDEX(REDBOOKSearchResults!$A$1:$AK$100, 0, MATCH($E$1, REDBOOKSearchResults!$1:$1, 0)), 0), MATCH(G$1, REDBOOKSearchResults!$1:$1, 0)) -> 21s ea
A3: =A2 -> POMALYST | B3: 45658 | C3: 1369.7714 | D3: 4.5 | E3: =E$2 -> 59572-0504-21 | F3: =INDEX(REDBOOKSearchResults!$A$1:$AK$100, MATCH($E3, INDEX(REDBOOKSearchResults!$A$1:$AK$100, 0, MATCH($E$1, REDBOOKSearchResults!$1:$1, 0)), 0), MATCH(F$1, REDBOOKSearchResults!$1:$1, 0)) -> 4 mg | G3: =INDEX(REDBOOKSearchResults!$A$1:$AK$100, MATCH($E3, INDEX(REDBOOKSearchResults!$A$1:$AK$100, 0, MATCH($E$1, REDBOOKSearchResults!$1:$1, 0)), 0), MATCH(G$1, REDBOOKSearchResults!$1:$1, 0)) -> 21s ea
A4: =A3 -> POMALYST | B4: 45292 | C4: 1310.7862 | D4: 6 | E4: =E$2 -> 59572-0504-21 | F4: =INDEX(REDBOOKSearchResults!$A$1:$AK$100, MATCH($E4, INDEX(REDBOOKSearchResults!$A$1:$AK$100, 0, MATCH($E$1, REDBOOKSearchResults!$1:$1, 0)), 0), MATCH(F$1, REDBOOKSearchResults!$1:$1, 0)) -> 4 mg | G4: =INDEX(REDBOOKSearchResults!$A$1:$AK$100, MATCH($E4, INDEX(REDBOOKSearchResults!$A$1:$AK$100, 0, MATCH($E$1, REDBOOKSearchResults!$1:$1, 0)), 0), MATCH(G$1, REDBOOKSearchResults!$1:$1, 0)) -> 21s ea
A5: =A4 -> POMALYST | B5: 45108 | C5: 1236.591 | D5: 2.5 | E5: =E$2 -> 59572-0504-21 | F5: =INDEX(REDBOOKSearchResults!$A$1:$AK$100, MATCH($E5, INDEX(REDBOOKSearchResults!$A$1:$AK$100, 0, MATCH($E$1, REDBOOKSearchResults!$1:$1, 0)), 0), MATCH(F$1, REDBOOKSearchResults!$1:$1, 0)) -> 4 mg | G5: =INDEX(REDBOOKSearchResults!$A$1:$AK$100, MATCH($E5, INDEX(REDBOOKSearchResults!$A$1:$AK$100, 0, MATCH($E$1, REDBOOKSearchResults!$1:$1, 0)), 0), MATCH(G$1, REDBOOKSearchResults!$1:$1, 0)) -> 21s ea
A6: =A5 -> POMALYST | B6: 44927 | C6: 1206.4305 | D6: 6 | E6: =E$2 -> 59572-0504-21 | F6: =INDEX(REDBOOKSearchResults!$A$1:$AK$100, MATCH($E6, INDEX(REDBOOKSearchResults!$A$1:$AK$100, 0, MATCH($E$1, REDBOOKSearchResults!$1:$1, 0)), 0), MATCH(F$1, REDBOOKSearchResults!$1:$1, 0)) -> 4 mg | G6: =INDEX(REDBOOKSearchResults!$A$1:$AK$100, MATCH($E6, INDEX(REDBOOKSearchResults!$A$1:$AK$100, 0, MATCH($E$1, REDBOOKSearchResults!$1:$1, 0)), 0), MATCH(G$1, REDBOOKSearchResults!$1:$1, 0)) -> 21s ea
A7: =A6 -> POMALYST | B7: 44562 | C7: 1138.1419 | D7: 4.5 | E7: =E$2 -> 59572-0504-21 | F7: =INDEX(REDBOOKSearchResults!$A$1:$AK$100, MATCH($E7, INDEX(REDBOOKSearchResults!$A$1:$AK$100, 0, MATCH($E$1, REDBOOKSearchResults!$1:$1, 0)), 0), MATCH(F$1, REDBOOKSearchResults!$1:$1, 0)) -> 4 mg | G7: =INDEX(REDBOOKSearchResults!$A$1:$AK$100, MATCH($E7, INDEX(REDBOOKSearchResults!$A$1:$AK$100, 0, MATCH($E$1, REDBOOKSearchResults!$1:$1, 0)), 0), MATCH(G$1, REDBOOKSearchResults!$1:$1, 0)) -> 21s ea
A8: =A7 -> POMALYST | B8: 44197 | C8: 1089.1309 | D8: 4.5 | E8: =E$2 -> 59572-0504-21 | F8: =INDEX(REDBOOKSearchResults!$A$1:$AK$100, MATCH($E8, INDEX(REDBOOKSearchResults!$A$1:$AK$100, 0, MATCH($E$1, REDBOOKSearchResults!$1:$1, 0)), 0), MATCH(F$1, REDBOOKSearchResults!$1:$1, 0)) -> 4 mg | G8: =INDEX(REDBOOKSearchResults!$A$1:$AK$100, MATCH($E8, INDEX(REDBOOKSearchResults!$A$1:$AK$100, 0, MATCH($E$1, REDBOOKSearchResults!$1:$1, 0)), 0), MATCH(G$1, REDBOOKSearchResults!$1:$1, 0)) -> 21s ea
A9: =A8 -> POMALYST | B9: 43831 | C9: 1042.2305 | D9: 6 | E9: =E$2 -> 59572-0504-21 | F9: =INDEX(REDBOOKSearchResults!$A$1:$AK$100, MATCH($E9, INDEX(REDBOOKSearchResults!$A$1:$AK$100, 0, MATCH($E$1, REDBOOKSearchResults!$1:$1, 0)), 0), MATCH(F$1, REDBOOKSearchResults!$1:$1, 0)) -> 4 mg | G9: =INDEX(REDBOOKSearchResults!$A$1:$AK$100, MATCH($E9, INDEX(REDBOOKSearchResults!$A$1:$AK$100, 0, MATCH($E$1, REDBOOKSearchResults!$1:$1, 0)), 0), MATCH(G$1, REDBOOKSearchResults!$1:$1, 0)) -> 21s ea
A10: =A9 -> POMALYST | B10: 43468 | C10: 983.23619 | D10: 3.5 | E10: =E$2 -> 59572-0504-21 | F10: =INDEX(REDBOOKSearchResults!$A$1:$AK$100, MATCH($E10, INDEX(REDBOOKSearchResults!$A$1:$AK$100, 0, MATCH($E$1, REDBOOKSearchResults!$1:$1, 0)), 0), MATCH(F$1, REDBOOKSearchResults!$1:$1, 0)) -> 4 mg | G10: =INDEX(REDBOOKSearchResults!$A$1:$AK$100, MATCH($E10, INDEX(REDBOOKSearchResults!$A$1:$AK$100, 0, MATCH($E$1, REDBOOKSearchResults!$1:$1, 0)), 0), MATCH(G$1, REDBOOKSearchResults!$1:$1, 0)) -> 21s ea
A11: =A10 -> POMALYST | B11: 43291 | C11: 949.98619 | D11: 5 | E11: =E$2 -> 59572-0504-21 | F11: =INDEX(REDBOOKSearchResults!$A$1:$AK$100, MATCH($E11, INDEX(REDBOOKSearchResults!$A$1:$AK$100, 0, MATCH($E$1, REDBOOKSearchResults!$1:$1, 0)), 0), MATCH(F$1, REDBOOKSearchResults!$1:$1, 0)) -> 4 mg | G11: =INDEX(REDBOOKSearchResults!$A$1:$AK$100, MATCH($E11, INDEX(REDBOOKSearchResults!$A$1:$AK$100, 0, MATCH($E$1, REDBOOKSearchResults!$1:$1, 0)), 0), MATCH(G$1, REDBOOKSearchResults!$1:$1, 0)) -> 21s ea
A12: =A11 -> POMALYST | B12: 43028 | C12: 904.74857 | D12: 9 | E12: =E$2 -> 59572-0504-21 | F12: =INDEX(REDBOOKSearchResults!$A$1:$AK$100, MATCH($E12, INDEX(REDBOOKSearchResults!$A$1:$AK$100, 0, MATCH($E$1, REDBOOKSearchResults!$1:$1, 0)), 0), MATCH(F$1, REDBOOKSearchResults!$1:$1, 0)) -> 4 mg | G12: =INDEX(REDBOOKSearchResults!$A$1:$AK$100, MATCH($E12, INDEX(REDBOOKSearchResults!$A$1:$AK$100, 0, MATCH($E$1, REDBOOKSearchResults!$1:$1, 0)), 0), MATCH(G$1, REDBOOKSearchResults!$1:$1, 0)) -> 21s ea
A13: =A12 -> POMALYST | B13: 42830 | C13: 830.04476 | D13: 8 | E13: =E$2 -> 59572-0504-21 | F13: =INDEX(REDBOOKSearchResults!$A$1:$AK$100, MATCH($E13, INDEX(REDBOOKSearchResults!$A$1:$AK$100, 0, MATCH($E$1, REDBOOKSearchResults!$1:$1, 0)), 0), MATCH(F$1, REDBOOKSearchResults!$1:$1, 0)) -> 4 mg | G13: =INDEX(REDBOOKSearchResults!$A$1:$AK$100, MATCH($E13, INDEX(REDBOOKSearchResults!$A$1:$AK$100, 0, MATCH($E$1, REDBOOKSearchResults!$1:$1, 0)), 0), MATCH(G$1, REDBOOKSearchResults!$1:$1, 0)) -> 21s ea
A14: =A13 -> POMALYST | B14: 42602 | C14: 768.56 | D14: 3 | E14: =E$2 -> 59572-0504-21 | F14: =INDEX(REDBOOKSearchResults!$A$1:$AK$100, MATCH($E14, INDEX(REDBOOKSearchResults!$A$1:$AK$100, 0, MATCH($E$1, REDBOOKSearchResults!$1:$1, 0)), 0), MATCH(F$1, REDBOOKSearchResults!$1:$1, 0)) -> 4 mg | G14: =INDEX(REDBOOKSearchResults!$A$1:$AK$100, MATCH($E14, INDEX(REDBOOKSearchResults!$A$1:$AK$100, 0, MATCH($E$1, REDBOOKSearchResults!$1:$1, 0)), 0), MATCH(G$1, REDBOOKSearchResults!$1:$1, 0)) -> 21s ea
... A21: =A20 -> POMALYST | B21: 41316 | C21: 596.88 | D21: 0 | E21: =E$2 -> 59572-0504-21 | F21: =INDEX(REDBOOKSearchResults!$A$1:$AK$100, MATCH($E21, INDEX(REDBOOKSearchResults!$A$1:$AK$100, 0, MATCH($E$1, REDBOOKSearchResults!$1:$1, 0)), 0), MATCH(F$1, REDBOOKSearchResults!$1:$1, 0)) -> 4 mg | G21: =INDEX(REDBOOKSearchResults!$A$1:$AK$100, MATCH($E21, INDEX(REDBOOKSearchResults!$A$1:$AK$100, 0, MATCH($E$1, REDBOOKSearchResults!$1:$1, 0)), 0), MATCH(G$1, REDBOOKSearchResults!$1:$1, 0)) -> 21s ea
A22: =A21 -> POMALYST | B22: 46023 | C22: 1431.411 | D22: 4.5 | E22: 59572-0504-00 | F22: =INDEX(REDBOOKSearchResults!$A$1:$AK$100, MATCH($E22, INDEX(REDBOOKSearchResults!$A$1:$AK$100, 0, MATCH($E$1, REDBOOKSearchResults!$1:$1, 0)), 0), MATCH(F$1, REDBOOKSearchResults!$1:$1, 0)) -> 4 mg | G22: =INDEX(REDBOOKSearchResults!$A$1:$AK$100, MATCH($E22, INDEX(REDBOOKSearchResults!$A$1:$AK$100, 0, MATCH($E$1, REDBOOKSearchResults!$1:$1, 0)), 0), MATCH(G$1, REDBOOKSearchResults!$1:$1, 0)) -> 100s ea
A23: =A22 -> POMALYST | B23: 45658 | C23: 1369.7713 | D23: 4.5 | E23: =E$22 -> 59572-0504-00 | F23: =INDEX(REDBOOKSearchResults!$A$1:$AK$100, MATCH($E23, INDEX(REDBOOKSearchResults!$A$1:$AK$100, 0, MATCH($E$1, REDBOOKSearchResults!$1:$1, 0)), 0), MATCH(F$1, REDBOOKSearchResults!$1:$1, 0)) -> 4 mg | G23: =INDEX(REDBOOKSearchResults!$A$1:$AK$100, MATCH($E23, INDEX(REDBOOKSearchResults!$A$1:$AK$100, 0, MATCH($E$1, REDBOOKSearchResults!$1:$1, 0)), 0), MATCH(G$1, REDBOOKSearchResults!$1:$1, 0)) -> 100s ea
A24: =A23 -> POMALYST | B24: 45292 | C24: 1310.7859 | D24: 6 | E24: =E$22 -> 59572-0504-00 | F24: =INDEX(REDBOOKSearchResults!$A$1:$AK$100, MATCH($E24, INDEX(REDBOOKSearchResults!$A$1:$AK$100, 0, MATCH($E$1, REDBOOKSearchResults!$1:$1, 0)), 0), MATCH(F$1, REDBOOKSearchResults!$1:$1, 0)) -> 4 mg | G24: =INDEX(REDBOOKSearchResults!$A$1:$AK$100, MATCH($E24, INDEX(REDBOOKSearchResults!$A$1:$AK$100, 0, MATCH($E$1, REDBOOKSearchResults!$1:$1, 0)), 0), MATCH(G$1, REDBOOKSearchResults!$1:$1, 0)) -> 100s ea
A25: =A24 -> POMALYST | B25: 45108 | C25: 1236.5905 | D25: 2.5 | E25: =E$22 -> 59572-0504-00 | F25: =INDEX(REDBOOKSearchResults!$A$1:$AK$100, MATCH($E25, INDEX(REDBOOKSearchResults!$A$1:$AK$100, 0, MATCH($E$1, REDBOOKSearchResults!$1:$1, 0)), 0), MATCH(F$1, REDBOOKSearchResults!$1:$1, 0)) -> 4 mg | G25: =INDEX(REDBOOKSearchResults!$A$1:$AK$100, MATCH($E25, INDEX(REDBOOKSearchResults!$A$1:$AK$100, 0, MATCH($E$1, REDBOOKSearchResults!$1:$1, 0)), 0), MATCH(G$1, REDBOOKSearchResults!$1:$1, 0)) -> 100s ea
A26: =A25 -> POMALYST | B26: 44927 | C26: 1206.4298 | D26: 6 | E26: =E$22 -> 59572-0504-00 | F26: =INDEX(REDBOOKSearchResults!$A$1:$AK$100, MATCH($E26, INDEX(REDBOOKSearchResults!$A$1:$AK$100, 0, MATCH($E$1, REDBOOKSearchResults!$1:$1, 0)), 0), MATCH(F$1, REDBOOKSearchResults!$1:$1, 0)) -> 4 mg | G26: =INDEX(REDBOOKSearchResults!$A$1:$AK$100, MATCH($E26, INDEX(REDBOOKSearchResults!$A$1:$AK$100, 0, MATCH($E$1, REDBOOKSearchResults!$1:$1, 0)), 0), MATCH(G$1, REDBOOKSearchResults!$1:$1, 0)) -> 100s ea
A27: =A26 -> POMALYST | B27: 44562 | C27: 1138.1412 | D27: 4.5 | E27: =E$22 -> 59572-0504-00 | F27: =INDEX(REDBOOKSearchResults!$A$1:$AK$100, MATCH($E27, INDEX(REDBOOKSearchResults!$A$1:$AK$100, 0, MATCH($E$1, REDBOOKSearchResults!$1:$1, 0)), 0), MATCH(F$1, REDBOOKSearchResults!$1:$1, 0)) -> 4 mg | G27: =INDEX(REDBOOKSearchResults!$A$1:$AK$100, MATCH($E27, INDEX(REDBOOKSearchResults!$A$1:$AK$100, 0, MATCH($E$1, REDBOOKSearchResults!$1:$1, 0)), 0), MATCH(G$1, REDBOOKSearchResults!$1:$1, 0)) -> 100s ea
A28: =A27 -> POMALYST | B28: 44197 | C28: 1089.1303 | D28: 4.5 | E28: =E$22 -> 59572-0504-00 | F28: =INDEX(REDBOOKSearchResults!$A$1:$AK$100, MATCH($E28, INDEX(REDBOOKSearchResults!$A$1:$AK$100, 0, MATCH($E$1, REDBOOKSearchResults!$1:$1, 0)), 0), MATCH(F$1, REDBOOKSearchResults!$1:$1, 0)) -> 4 mg | G28: =INDEX(REDBOOKSearchResults!$A$1:$AK$100, MATCH($E28, INDEX(REDBOOKSearchResults!$A$1:$AK$100, 0, MATCH($E$1, REDBOOKSearchResults!$1:$1, 0)), 0), MATCH(G$1, REDBOOKSearchResults!$1:$1, 0)) -> 100s ea
A29: =A28 -> POMALYST | B29: 43831 | C29: 1042.23 | D29: 6 | E29: =E$22 -> 59572-0504-00 | F29: =INDEX(REDBOOKSearchResults!$A$1:$AK$100, MATCH($E29, INDEX(REDBOOKSearchResults!$A$1:$AK$100, 0, MATCH($E$1, REDBOOKSearchResults!$1:$1, 0)), 0), MATCH(F$1, REDBOOKSearchResults!$1:$1, 0)) -> 4 mg | G29: =INDEX(REDBOOKSearchResults!$A$1:$AK$100, MATCH($E29, INDEX(REDBOOKSearchResults!$A$1:$AK$100, 0, MATCH($E$1, REDBOOKSearchResults!$1:$1, 0)), 0), MATCH(G$1, REDBOOKSearchResults!$1:$1, 0)) -> 100s ea
A30: =A29 -> POMALYST | B30: 43468 | C30: 983.2359 | D30: 3.5 | E30: =E$22 -> 59572-0504-00 | F30: =INDEX(REDBOOKSearchResults!$A$1:$AK$100, MATCH($E30, INDEX(REDBOOKSearchResults!$A$1:$AK$100, 0, MATCH($E$1, REDBOOKSearchResults!$1:$1, 0)), 0), MATCH(F$1, REDBOOKSearchResults!$1:$1, 0)) -> 4 mg | G30: =INDEX(REDBOOKSearchResults!$A$1:$AK$100, MATCH($E30, INDEX(REDBOOKSearchResults!$A$1:$AK$100, 0, MATCH($E$1, REDBOOKSearchResults!$1:$1, 0)), 0), MATCH(G$1, REDBOOKSearchResults!$1:$1, 0)) -> 100s ea
A31: =A30 -> POMALYST | B31: 43291 | C31: 949.9864 | D31: 5 | E31: =E$22 -> 59572-0504-00 | F31: =INDEX(REDBOOKSearchResults!$A$1:$AK$100, MATCH($E31, INDEX(REDBOOKSearchResults!$A$1:$AK$100, 0, MATCH($E$1, REDBOOKSearchResults!$1:$1, 0)), 0), MATCH(F$1, REDBOOKSearchResults!$1:$1, 0)) -> 4 mg | G31: =INDEX(REDBOOKSearchResults!$A$1:$AK$100, MATCH($E31, INDEX(REDBOOKSearchResults!$A$1:$AK$100, 0, MATCH($E$1, REDBOOKSearchResults!$1:$1, 0)), 0), MATCH(G$1, REDBOOKSearchResults!$1:$1, 0)) -> 100s ea
A32: =A31 -> POMALYST | B32: 43028 | C32: 904.7489 | D32: 9 | E32: =E$22 -> 59572-0504-00 | F32: =INDEX(REDBOOKSearchResults!$A$1:$AK$100, MATCH($E32, INDEX(REDBOOKSearchResults!$A$1:$AK$100, 0, MATCH($E$1, REDBOOKSearchResults!$1:$1, 0)), 0), MATCH(F$1, REDBOOKSearchResults!$1:$1, 0)) -> 4 mg | G32: =INDEX(REDBOOKSearchResults!$A$1:$AK$100, MATCH($E32, INDEX(REDBOOKSearchResults!$A$1:$AK$100, 0, MATCH($E$1, REDBOOKSearchResults!$1:$1, 0)), 0), MATCH(G$1, REDBOOKSearchResults!$1:$1, 0)) -> 100s ea
A33: =A32 -> POMALYST | B33: 42830 | C33: 830.0448 | D33: 8 | E33: =E$22 -> 59572-0504-00 | F33: =INDEX(REDBOOKSearchResults!$A$1:$AK$100, MATCH($E33, INDEX(REDBOOKSearchResults!$A$1:$AK$100, 0, MATCH($E$1, REDBOOKSearchResults!$1:$1, 0)), 0), MATCH(F$1, REDBOOKSearchResults!$1:$1, 0)) -> 4 mg | G33: =INDEX(REDBOOKSearchResults!$A$1:$AK$100, MATCH($E33, INDEX(REDBOOKSearchResults!$A$1:$AK$100, 0, MATCH($E$1, REDBOOKSearchResults!$1:$1, 0)), 0), MATCH(G$1, REDBOOKSearchResults!$1:$1, 0)) -> 100s ea
A34: =A33 -> POMALYST | B34: 42602 | C34: 768.5601 | D34: 3 | E34: =E$22 -> 59572-0504-00 | F34: =INDEX(REDBOOKSearchResults!$A$1:$AK$100, MATCH($E34, INDEX(REDBOOKSearchResults!$A$1:$AK$100, 0, MATCH($E$1, REDBOOKSearchResults!$1:$1, 0)), 0), MATCH(F$1, REDBOOKSearchResults!$1:$1, 0)) -> 4 mg | G34: =INDEX(REDBOOKSearchResults!$A$1:$AK$100, MATCH($E34, INDEX(REDBOOKSearchResults!$A$1:$AK$100, 0, MATCH($E$1, REDBOOKSearchResults!$1:$1, 0)), 0), MATCH(G$1, REDBOOKSearchResults!$1:$1, 0)) -> 100s ea
... A41: =A40 -> POMALYST | B41: 41316 | C41: 596.88 | D41: 0 | E41: =E$22 -> 59572-0504-00 | F41: =INDEX(REDBOOKSearchResults!$A$1:$AK$100, MATCH($E41, INDEX(REDBOOKSearchResults!$A$1:$AK$100, 0, MATCH($E$1, REDBOOKSearchResults!$1:$1, 0)), 0), MATCH(F$1, REDBOOKSearchResults!$1:$1, 0)) -> 4 mg | G41: =INDEX(REDBOOKSearchResults!$A$1:$AK$100, MATCH($E41, INDEX(REDBOOKSearchResults!$A$1:$AK$100, 0, MATCH($E$1, REDBOOKSearchResults!$1:$1, 0)), 0), MATCH(G$1, REDBOOKSearchResults!$1:$1, 0)) -> 100s ea
A42: =A41 -> POMALYST | B42: 46023 | C42: 1431.4114 | D42: 4.5 | E42: 59572-0503-21 | F42: =INDEX(REDBOOKSearchResults!$A$1:$AK$100, MATCH($E42, INDEX(REDBOOKSearchResults!$A$1:$AK$100, 0, MATCH($E$1, REDBOOKSearchResults!$1:$1, 0)), 0), MATCH(F$1, REDBOOKSearchResults!$1:$1, 0)) -> 3 mg | G42: =INDEX(REDBOOKSearchResults!$A$1:$AK$100, MATCH($E42, INDEX(REDBOOKSearchResults!$A$1:$AK$100, 0, MATCH($E$1, REDBOOKSearchResults!$1:$1, 0)), 0), MATCH(G$1, REDBOOKSearchResults!$1:$1, 0)) -> 21s ea
A43: =A42 -> POMALYST | B43: 45658 | C43: 1369.7714 | D43: 4.5 | E43: =E$42 -> 59572-0503-21 | F43: =INDEX(REDBOOKSearchResults!$A$1:$AK$100, MATCH($E43, INDEX(REDBOOKSearchResults!$A$1:$AK$100, 0, MATCH($E$1, REDBOOKSearchResults!$1:$1, 0)), 0), MATCH(F$1, REDBOOKSearchResults!$1:$1, 0)) -> 3 mg | G43: =INDEX(REDBOOKSearchResults!$A$1:$AK$100, MATCH($E43, INDEX(REDBOOKSearchResults!$A$1:$AK$100, 0, MATCH($E$1, REDBOOKSearchResults!$1:$1, 0)), 0), MATCH(G$1, REDBOOKSearchResults!$1:$1, 0)) -> 21s ea
A44: =A43 -> POMALYST | B44: 45292 | C44: 1310.7862 | D44: 6 | E44: =E$42 -> 59572-0503-21 | F44: =INDEX(REDBOOKSearchResults!$A$1:$AK$100, MATCH($E44, INDEX(REDBOOKSearchResults!$A$1:$AK$100, 0, MATCH($E$1, REDBOOKSearchResults!$1:$1, 0)), 0), MATCH(F$1, REDBOOKSearchResults!$1:$1, 0)) -> 3 mg | G44: =INDEX(REDBOOKSearchResults!$A$1:$AK$100, MATCH($E44, INDEX(REDBOOKSearchResults!$A$1:$AK$100, 0, MATCH($E$1, REDBOOKSearchResults!$1:$1, 0)), 0), MATCH(G$1, REDBOOKSearchResults!$1:$1, 0)) -> 21s ea
A45: =A44 -> POMALYST | B45: 45108 | C45: 1236.591 | D45: 2.5 | E45: =E$42 -> 59572-0503-21 | F45: =INDEX(REDBOOKSearchResults!$A$1:$AK$100, MATCH($E45, INDEX(REDBOOKSearchResults!$A$1:$AK$100, 0, MATCH($E$1, REDBOOKSearchResults!$1:$1, 0)), 0), MATCH(F$1, REDBOOKSearchResults!$1:$1, 0)) -> 3 mg | G45: =INDEX(REDBOOKSearchResults!$A$1:$AK$100, MATCH($E45, INDEX(REDBOOKSearchResults!$A$1:$AK$100, 0, MATCH($E$1, REDBOOKSearchResults!$1:$1, 0)), 0), MATCH(G$1, REDBOOKSearchResults!$1:$1, 0)) -> 21s ea
A46: =A45 -> POMALYST | B46: 44927 | C46: 1206.4305 | D46: 6 | E46: =E$42 -> 59572-0503-21 | F46: =INDEX(REDBOOKSearchResults!$A$1:$AK$100, MATCH($E46, INDEX(REDBOOKSearchResults!$A$1:$AK$100, 0, MATCH($E$1, REDBOOKSearchResults!$1:$1, 0)), 0), MATCH(F$1, REDBOOKSearchResults!$1:$1, 0)) -> 3 mg | G46: =INDEX(REDBOOKSearchResults!$A$1:$AK$100, MATCH($E46, INDEX(REDBOOKSearchResults!$A$1:$AK$100, 0, MATCH($E$1, REDBOOKSearchResults!$1:$1, 0)), 0), MATCH(G$1, REDBOOKSearchResults!$1:$1, 0)) -> 21s ea
A47: =A46 -> POMALYST | B47: 44562 | C47: 1138.1419 | D47: 4.5 | E47: =E$42 -> 59572-0503-21 | F47: =INDEX(REDBOOKSearchResults!$A$1:$AK$100, MATCH($E47, INDEX(REDBOOKSearchResults!$A$1:$AK$100, 0, MATCH($E$1, REDBOOKSearchResults!$1:$1, 0)), 0), MATCH(F$1, REDBOOKSearchResults!$1:$1, 0)) -> 3 mg | G47: =INDEX(REDBOOKSearchResults!$A$1:$AK$100, MATCH($E47, INDEX(REDBOOKSearchResults!$A$1:$AK$100, 0, MATCH($E$1, REDBOOKSearchResults!$1:$1, 0)), 0), MATCH(G$1, REDBOOKSearchResults!$1:$1, 0)) -> 21s ea
A48: =A47 -> POMALYST | B48: 44197 | C48: 1089.1309 | D48: 4.5 | E48: =E$42 -> 59572-0503-21 | F48: =INDEX(REDBOOKSearchResults!$A$1:$AK$100, MATCH($E48, INDEX(REDBOOKSearchResults!$A$1:$AK$100, 0, MATCH($E$1, REDBOOKSearchResults!$1:$1, 0)), 0), MATCH(F$1, REDBOOKSearchResults!$1:$1, 0)) -> 3 mg | G48: =INDEX(REDBOOKSearchResults!$A$1:$AK$100, MATCH($E48, INDEX(REDBOOKSearchResults!$A$1:$AK$100, 0, MATCH($E$1, REDBOOKSearchResults!$1:$1, 0)), 0), MATCH(G$1, REDBOOKSearchResults!$1:$1, 0)) -> 21s ea
A49: =A48 -> POMALYST | B49: 43831 | C49: 1042.2305 | D49: 6 | E49: =E$42 -> 59572-0503-21 | F49: =INDEX(REDBOOKSearchResults!$A$1:$AK$100, MATCH($E49, INDEX(REDBOOKSearchResults!$A$1:$AK$100, 0, MATCH($E$1, REDBOOKSearchResults!$1:$1, 0)), 0), MATCH(F$1, REDBOOKSearchResults!$1:$1, 0)) -> 3 mg | G49: =INDEX(REDBOOKSearchResults!$A$1:$AK$100, MATCH($E49, INDEX(REDBOOKSearchResults!$A$1:$AK$100, 0, MATCH($E$1, REDBOOKSearchResults!$1:$1, 0)), 0), MATCH(G$1, REDBOOKSearchResults!$1:$1, 0)) -> 21s ea
A50: =A49 -> POMALYST | B50: 43468 | C50: 983.23619 | D50: 3.5 | E50: =E$42 -> 59572-0503-21 | F50: =INDEX(REDBOOKSearchResults!$A$1:$AK$100, MATCH($E50, INDEX(REDBOOKSearchResults!$A$1:$AK$100, 0, MATCH($E$1, REDBOOKSearchResults!$1:$1, 0)), 0), MATCH(F$1, REDBOOKSearchResults!$1:$1, 0)) -> 3 mg | G50: =INDEX(REDBOOKSearchResults!$A$1:$AK$100, MATCH($E50, INDEX(REDBOOKSearchResults!$A$1:$AK$100, 0, MATCH($E$1, REDBOOKSearchResults!$1:$1, 0)), 0), MATCH(G$1, REDBOOKSearchResults!$1:$1, 0)) -> 21s ea
A51: =A50 -> POMALYST | B51: 43291 | C51: 949.98619 | D51: 5 | E51: =E$42 -> 59572-0503-21 | F51: =INDEX(REDBOOKSearchResults!$A$1:$AK$100, MATCH($E51, INDEX(REDBOOKSearchResults!$A$1:$AK$100, 0, MATCH($E$1, REDBOOKSearchResults!$1:$1, 0)), 0), MATCH(F$1, REDBOOKSearchResults!$1:$1, 0)) -> 3 mg | G51: =INDEX(REDBOOKSearchResults!$A$1:$AK$100, MATCH($E51, INDEX(REDBOOKSearchResults!$A$1:$AK$100, 0, MATCH($E$1, REDBOOKSearchResults!$1:$1, 0)), 0), MATCH(G$1, REDBOOKSearchResults!$1:$1, 0)) -> 21s ea
A52: =A51 -> POMALYST | B52: 43028 | C52: 904.74857 | D52: 9 | E52: =E$42 -> 59572-0503-21 | F52: =INDEX(REDBOOKSearchResults!$A$1:$AK$100, MATCH($E52, INDEX(REDBOOKSearchResults!$A$1:$AK$100, 0, MATCH($E$1, REDBOOKSearchResults!$1:$1, 0)), 0), MATCH(F$1, REDBOOKSearchResults!$1:$1, 0)) -> 3 mg | G52: =INDEX(REDBOOKSearchResults!$A$1:$AK$100, MATCH($E52, INDEX(REDBOOKSearchResults!$A$1:$AK$100, 0, MATCH($E$1, REDBOOKSearchResults!$1:$1, 0)), 0), MATCH(G$1, REDBOOKSearchResults!$1:$1, 0)) -> 21s ea
...
